[LOG] HandleNewTask(): Received new task 0 at time 62073
[LOG] Scheduler::NewTask(): Task 0 requires VM=0 CPU=3 SLA=1 GPU=no Memory=8 TargetCompletion=8868538 Arrival=62073
[DEBUG] Creating new VM for task 0
[LOG] Scheduler::NewTask(): Task 0 placed on VM 0 (priority=0) VM now has 1 tasks, Machine 0 has 1 tasks, 16/16384 memory
[LOG] HandleTaskCompletion(): Task 0 completed at time 330894
[LOG] Scheduler::TaskComplete(): Task 0 completed at 330894 (target=8868538, delay=-8537644, SLA violated=NO)
[LOG] HandleNewTask(): Received new task 1 at time 333607
[LOG] Scheduler::NewTask(): Task 1 requires VM=0 CPU=3 SLA=1 GPU=no Memory=8 TargetCompletion=9372523 Arrival=333607
[DEBUG] Selected VM 0 with 0 active tasks on machine 0
[LOG] Scheduler::NewTask(): Task 1 placed on VM 0 (priority=0) VM now has 1 tasks, Machine 0 has 1 tasks, 16/16384 memory
[LOG] HandleNewTask(): Received new task 2 at time 637358
[LOG] Scheduler::NewTask(): Task 2 requires VM=0 CPU=3 SLA=1 GPU=no Memory=8 TargetCompletion=9304901 Arrival=637358
[DEBUG] Selected VM 0 with 1 active tasks on machine 0
[LOG] Scheduler::NewTask(): Task 2 placed on VM 0 (priority=0) VM now has 2 tasks, Machine 0 has 2 tasks, 24/16384 memory
[LOG] HandleTaskCompletion(): Task 1 completed at time 679912
[LOG] Scheduler::TaskComplete(): Task 1 completed at 679912 (target=9372523, delay=-8692611, SLA violated=NO)
[LOG] HandleNewTask(): Received new task 3 at time 722677
[LOG] Scheduler::NewTask(): Task 3 requires VM=0 CPU=3 SLA=1 GPU=no Memory=8 TargetCompletion=9903718 Arrival=722677
[DEBUG] Selected VM 0 with 1 active tasks on machine 0
[LOG] Scheduler::NewTask(): Task 3 placed on VM 0 (priority=0) VM now has 2 tasks, Machine 0 has 2 tasks, 24/16384 memory
[LOG] HandleNewTask(): Received new task 4 at time 759499
[LOG] Scheduler::NewTask(): Task 4 requires VM=0 CPU=3 SLA=1 GPU=no Memory=8 TargetCompletion=9954635 Arrival=759499
[DEBUG] Selected VM 0 with 2 active tasks on machine 0
[LOG] Scheduler::NewTask(): Task 4 placed on VM 0 (priority=0) VM now has 3 tasks, Machine 0 has 3 tasks, 32/16384 memory
[LOG] HandleNewTask(): Received new task 5 at time 787982
[LOG] Scheduler::NewTask(): Task 5 requires VM=0 CPU=3 SLA=1 GPU=no Memory=8 TargetCompletion=9977543 Arrival=787982
[DEBUG] VM 0 has 3 tasks in queue, creating new VM for load balancing
[DEBUG] Creating new VM for task 5
[DEBUG] Created new VM 1 on machine 1
[LOG] Scheduler::NewTask(): Task 5 placed on VM 1 (priority=0) VM now has 1 tasks, Machine 1 has 1 tasks, 16/16384 memory
[LOG] HandleTaskCompletion(): Task 2 completed at time 859872
[LOG] Scheduler::TaskComplete(): Task 2 completed at 859872 (target=9304901, delay=-8445029, SLA violated=NO)
[LOG] HandleNewTask(): Received new task 6 at time 902269
[LOG] Scheduler::NewTask(): Task 6 requires VM=0 CPU=3 SLA=1 GPU=no Memory=8 TargetCompletion=9927256 Arrival=902269
[DEBUG] Selected VM 1 with 1 active tasks on machine 1
[LOG] Scheduler::NewTask(): Task 6 placed on VM 1 (priority=0) VM now has 2 tasks, Machine 1 has 2 tasks, 24/16384 memory
[LOG] HandleTaskCompletion(): Task 3 completed at time 1116357
[LOG] Scheduler::TaskComplete(): Task 3 completed at 1116357 (target=9903718, delay=-8787361, SLA violated=NO)
[LOG] HandleTaskCompletion(): Task 4 completed at time 1157877
[LOG] Scheduler::TaskComplete(): Task 4 completed at 1157877 (target=9954635, delay=-8796758, SLA violated=NO)
[LOG] HandleTaskCompletion(): Task 5 completed at time 1184502
[LOG] Scheduler::TaskComplete(): Task 5 completed at 1184502 (target=9977543, delay=-8793041, SLA violated=NO)
[LOG] Scheduler::consolidateMachines(): Powering down idle machine 2 (active machines: 24)
[LOG] Scheduler::consolidateMachines(): Powering down idle machine 3 (active machines: 23)
[LOG] Scheduler::consolidateMachines(): Powering down idle machine 4 (active machines: 22)
[LOG] Scheduler::consolidateMachines(): Powering down idle machine 5 (active machines: 21)
[LOG] Scheduler::consolidateMachines(): Powering down idle machine 6 (active machines: 20)
[LOG] Scheduler::consolidateMachines(): Powering down idle machine 7 (active machines: 19)
[LOG] Scheduler::consolidateMachines(): Powering down idle machine 8 (active machines: 18)
[LOG] Scheduler::consolidateMachines(): Powering down idle machine 9 (active machines: 17)
[LOG] Scheduler::consolidateMachines(): Powering down idle machine 10 (active machines: 16)
[LOG] Scheduler::consolidateMachines(): Powering down idle machine 11 (active machines: 15)
[LOG] Scheduler::consolidateMachines(): Powering down idle machine 12 (active machines: 14)
[LOG] Scheduler::consolidateMachines(): Powering down idle machine 13 (active machines: 13)
[LOG] Scheduler::consolidateMachines(): Powering down idle machine 14 (active machines: 12)
[LOG] Scheduler::consolidateMachines(): Powering down idle machine 15 (active machines: 11)
[LOG] Scheduler::consolidateMachines(): Powering down idle machine 16 (active machines: 10)
[LOG] Scheduler::consolidateMachines(): Powering down idle machine 17 (active machines: 9)
[LOG] Scheduler::consolidateMachines(): Powering down idle machine 18 (active machines: 8)
[LOG] Scheduler::consolidateMachines(): Powering down idle machine 19 (active machines: 7)
[LOG] Scheduler::consolidateMachines(): Powering down idle machine 20 (active machines: 6)
[LOG] Scheduler::consolidateMachines(): Powering down idle machine 21 (active machines: 5)
[LOG] HandleNewTask(): Received new task 7 at time 1235725
[LOG] Scheduler::NewTask(): Task 7 requires VM=0 CPU=3 SLA=1 GPU=no Memory=8 TargetCompletion=10156458 Arrival=1235725
[DEBUG] Selected VM 0 with 0 active tasks on machine 0
[LOG] Scheduler::NewTask(): Task 7 placed on VM 2 (priority=0) VM now has 1 tasks, Machine 0 has 1 tasks, 16/16384 memory
[LOG] HandleTaskCompletion(): Task 6 completed at time 1243931
[LOG] Scheduler::TaskComplete(): Task 6 completed at 1243931 (target=9927256, delay=-8683325, SLA violated=NO)
[LOG] HandleNewTask(): Received new task 8 at time 1244393
[LOG] Scheduler::NewTask(): Task 8 requires VM=0 CPU=3 SLA=1 GPU=no Memory=8 TargetCompletion=10116793 Arrival=1244393
[DEBUG] Selected VM 0 with 0 active tasks on machine 0
[LOG] Scheduler::NewTask(): Task 8 placed on VM 3 (priority=0) VM now has 1 tasks, Machine 2 has 1 tasks, 16/16384 memory
[LOG] HandleNewTask(): Received new task 9 at time 1310280
[LOG] Scheduler::NewTask(): Task 9 requires VM=0 CPU=3 SLA=1 GPU=no Memory=8 TargetCompletion=10573748 Arrival=1310280
[DEBUG] Selected VM 0 with 0 active tasks on machine 0
[LOG] Scheduler::NewTask(): Task 9 placed on VM 4 (priority=0) VM now has 1 tasks, Machine 3 has 1 tasks, 16/16384 memory
[LOG] HandleNewTask(): Received new task 10 at time 1325910
[LOG] Scheduler::NewTask(): Task 10 requires VM=0 CPU=3 SLA=1 GPU=no Memory=8 TargetCompletion=10054073 Arrival=1325910
[DEBUG] Selected VM 0 with 0 active tasks on machine 0
[LOG] Scheduler::NewTask(): Task 10 placed on VM 5 (priority=0) VM now has 1 tasks, Machine 4 has 1 tasks, 16/16384 memory
[LOG] HandleNewTask(): Received new task 11 at time 1456501
[LOG] Scheduler::NewTask(): Task 11 requires VM=0 CPU=3 SLA=1 GPU=no Memory=8 TargetCompletion=10334613 Arrival=1456501
[DEBUG] Selected VM 0 with 0 active tasks on machine 0
[LOG] Scheduler::NewTask(): Task 11 placed on VM 6 (priority=0) VM now has 1 tasks, Machine 5 has 1 tasks, 16/16384 memory
[LOG] HandleTaskCompletion(): Task 8 completed at time 1535193
[LOG] Scheduler::TaskComplete(): Task 8 completed at 1535193 (target=10116793, delay=-8581600, SLA violated=NO)
[LOG] HandleTaskCompletion(): Task 7 completed at time 1542636
[LOG] Scheduler::TaskComplete(): Task 7 completed at 1542636 (target=10156458, delay=-8613822, SLA violated=NO)
[LOG] HandleTaskCompletion(): Task 10 completed at time 1568631
[LOG] Scheduler::TaskComplete(): Task 10 completed at 1568631 (target=10054073, delay=-8485442, SLA violated=NO)
[LOG] Scheduler::consolidateMachines(): Powering down idle machine 6 (active machines: 24)
[LOG] Scheduler::consolidateMachines(): Powering down idle machine 7 (active machines: 23)
[LOG] Scheduler::consolidateMachines(): Powering down idle machine 8 (active machines: 22)
[LOG] Scheduler::consolidateMachines(): Powering down idle machine 9 (active machines: 21)
[LOG] Scheduler::consolidateMachines(): Powering down idle machine 10 (active machines: 20)
[LOG] Scheduler::consolidateMachines(): Powering down idle machine 11 (active machines: 19)
[LOG] Scheduler::consolidateMachines(): Powering down idle machine 12 (active machines: 18)
[LOG] Scheduler::consolidateMachines(): Powering down idle machine 13 (active machines: 17)
[LOG] Scheduler::consolidateMachines(): Powering down idle machine 14 (active machines: 16)
[LOG] Scheduler::consolidateMachines(): Powering down idle machine 15 (active machines: 15)
[LOG] Scheduler::consolidateMachines(): Powering down idle machine 16 (active machines: 14)
[LOG] Scheduler::consolidateMachines(): Powering down idle machine 17 (active machines: 13)
[LOG] Scheduler::consolidateMachines(): Powering down idle machine 18 (active machines: 12)
[LOG] Scheduler::consolidateMachines(): Powering down idle machine 19 (active machines: 11)
[LOG] Scheduler::consolidateMachines(): Powering down idle machine 20 (active machines: 10)
[LOG] Scheduler::consolidateMachines(): Powering down idle machine 21 (active machines: 9)
[LOG] Scheduler::consolidateMachines(): Powering down idle machine 22 (active machines: 8)
[LOG] Scheduler::consolidateMachines(): Powering down idle machine 23 (active machines: 7)
[LOG] HandleNewTask(): Received new task 12 at time 1598442
[LOG] Scheduler::NewTask(): Task 12 requires VM=0 CPU=3 SLA=1 GPU=no Memory=8 TargetCompletion=10551543 Arrival=1598442
[DEBUG] Selected VM 0 with 0 active tasks on machine 0
[LOG] Scheduler::NewTask(): Task 12 placed on VM 7 (priority=0) VM now has 1 tasks, Machine 0 has 1 tasks, 16/16384 memory
[LOG] HandleNewTask(): Received new task 13 at time 1711749
[LOG] Scheduler::NewTask(): Task 13 requires VM=0 CPU=3 SLA=1 GPU=no Memory=8 TargetCompletion=10371844 Arrival=1711749
[DEBUG] Selected VM 0 with 0 active tasks on machine 0
[LOG] Scheduler::NewTask(): Task 13 placed on VM 8 (priority=0) VM now has 1 tasks, Machine 1 has 1 tasks, 16/16384 memory
[LOG] HandleTaskCompletion(): Task 9 completed at time 1731436
[LOG] Scheduler::TaskComplete(): Task 9 completed at 1731436 (target=10573748, delay=-8842312, SLA violated=NO)
[LOG] HandleTaskCompletion(): Task 11 completed at time 1749205
[LOG] Scheduler::TaskComplete(): Task 11 completed at 1749205 (target=10334613, delay=-8585408, SLA violated=NO)
[LOG] HandleTaskCompletion(): Task 12 completed at time 1916142
[LOG] Scheduler::TaskComplete(): Task 12 completed at 1916142 (target=10551543, delay=-8635401, SLA violated=NO)
[LOG] HandleTaskCompletion(): Task 13 completed at time 1931780
[LOG] Scheduler::TaskComplete(): Task 13 completed at 1931780 (target=10371844, delay=-8440064, SLA violated=NO)
[LOG] HandleNewTask(): Received new task 14 at time 2038794
[LOG] Scheduler::NewTask(): Task 14 requires VM=0 CPU=3 SLA=1 GPU=no Memory=8 TargetCompletion=11121742 Arrival=2038794
[DEBUG] Selected VM 0 with 0 active tasks on machine 0
[LOG] Scheduler::NewTask(): Task 14 placed on VM 9 (priority=0) VM now has 1 tasks, Machine 2 has 1 tasks, 16/16384 memory
[LOG] HandleNewTask(): Received new task 15 at time 2368172
[LOG] Scheduler::NewTask(): Task 15 requires VM=0 CPU=3 SLA=1 GPU=no Memory=8 TargetCompletion=11357276 Arrival=2368172
[DEBUG] Selected VM 0 with 0 active tasks on machine 0
[LOG] Scheduler::NewTask(): Task 15 placed on VM 10 (priority=0) VM now has 1 tasks, Machine 4 has 1 tasks, 16/16384 memory
[LOG] HandleNewTask(): Received new task 16 at time 2392064
[LOG] Scheduler::NewTask(): Task 16 requires VM=0 CPU=3 SLA=1 GPU=no Memory=8 TargetCompletion=11159970 Arrival=2392064
[DEBUG] Selected VM 0 with 0 active tasks on machine 0
[LOG] Scheduler::NewTask(): Task 16 placed on VM 11 (priority=0) VM now has 1 tasks, Machine 6 has 1 tasks, 16/16384 memory
[LOG] HandleTaskCompletion(): Task 14 completed at time 2399776
[LOG] Scheduler::TaskComplete(): Task 14 completed at 2399776 (target=11121742, delay=-8721966, SLA violated=NO)
[LOG] Scheduler::consolidateMachines(): Powering down idle machine 7 (active machines: 24)
[LOG] Scheduler::consolidateMachines(): Powering down idle machine 8 (active machines: 23)
[LOG] Scheduler::consolidateMachines(): Powering down idle machine 9 (active machines: 22)
[LOG] Scheduler::consolidateMachines(): Powering down idle machine 10 (active machines: 21)
[LOG] Scheduler::consolidateMachines(): Powering down idle machine 11 (active machines: 20)
[LOG] Scheduler::consolidateMachines(): Powering down idle machine 12 (active machines: 19)
[LOG] Scheduler::consolidateMachines(): Powering down idle machine 13 (active machines: 18)
[LOG] Scheduler::consolidateMachines(): Powering down idle machine 14 (active machines: 17)
[LOG] Scheduler::consolidateMachines(): Powering down idle machine 15 (active machines: 16)
[LOG] Scheduler::consolidateMachines(): Powering down idle machine 16 (active machines: 15)
[LOG] Scheduler::consolidateMachines(): Powering down idle machine 17 (active machines: 14)
[LOG] Scheduler::consolidateMachines(): Powering down idle machine 18 (active machines: 13)
[LOG] Scheduler::consolidateMachines(): Powering down idle machine 19 (active machines: 12)
[LOG] Scheduler::consolidateMachines(): Powering down idle machine 20 (active machines: 11)
[LOG] Scheduler::consolidateMachines(): Powering down idle machine 21 (active machines: 10)
[LOG] Scheduler::consolidateMachines(): Powering down idle machine 22 (active machines: 9)
[LOG] Scheduler::consolidateMachines(): Powering down idle machine 23 (active machines: 8)
[LOG] HandleNewTask(): Received new task 17 at time 2412436
[LOG] Scheduler::NewTask(): Task 17 requires VM=0 CPU=3 SLA=1 GPU=no Memory=8 TargetCompletion=11549910 Arrival=2412436
[DEBUG] Selected VM 0 with 0 active tasks on machine 0
[LOG] Scheduler::NewTask(): Task 17 placed on VM 12 (priority=0) VM now has 1 tasks, Machine 0 has 1 tasks, 16/16384 memory
[LOG] HandleNewTask(): Received new task 18 at time 2486391
[LOG] Scheduler::NewTask(): Task 18 requires VM=0 CPU=3 SLA=1 GPU=no Memory=8 TargetCompletion=11830422 Arrival=2486391
[DEBUG] Selected VM 0 with 0 active tasks on machine 0
[LOG] Scheduler::NewTask(): Task 18 placed on VM 13 (priority=0) VM now has 1 tasks, Machine 1 has 1 tasks, 16/16384 memory
[LOG] HandleNewTask(): Received new task 19 at time 2489829
[LOG] Scheduler::NewTask(): Task 19 requires VM=0 CPU=3 SLA=1 GPU=no Memory=8 TargetCompletion=11392590 Arrival=2489829
[DEBUG] Selected VM 0 with 0 active tasks on machine 0
[LOG] Scheduler::NewTask(): Task 19 placed on VM 14 (priority=0) VM now has 1 tasks, Machine 2 has 1 tasks, 16/16384 memory
[LOG] HandleNewTask(): Received new task 20 at time 2511912
[LOG] Scheduler::NewTask(): Task 20 requires VM=0 CPU=3 SLA=1 GPU=no Memory=8 TargetCompletion=11750652 Arrival=2511912
[DEBUG] Selected VM 0 with 0 active tasks on machine 0
[LOG] Scheduler::NewTask(): Task 20 placed on VM 15 (priority=0) VM now has 1 tasks, Machine 3 has 1 tasks, 16/16384 memory
[LOG] HandleNewTask(): Received new task 21 at time 2522168
[LOG] Scheduler::NewTask(): Task 21 requires VM=0 CPU=3 SLA=1 GPU=no Memory=8 TargetCompletion=11420427 Arrival=2522168
[DEBUG] Selected VM 0 with 0 active tasks on machine 0
[LOG] Scheduler::NewTask(): Task 21 placed on VM 16 (priority=0) VM now has 1 tasks, Machine 5 has 1 tasks, 16/16384 memory
[LOG] HandleTaskCompletion(): Task 16 completed at time 2648032
[LOG] Scheduler::TaskComplete(): Task 16 completed at 2648032 (target=11159970, delay=-8511938, SLA violated=NO)
[LOG] HandleTaskCompletion(): Task 15 completed at time 2697873
[LOG] Scheduler::TaskComplete(): Task 15 completed at 2697873 (target=11357276, delay=-8659403, SLA violated=NO)
[LOG] HandleTaskCompletion(): Task 19 completed at time 2790749
[LOG] Scheduler::TaskComplete(): Task 19 completed at 2790749 (target=11392590, delay=-8601841, SLA violated=NO)
[LOG] HandleTaskCompletion(): Task 17 completed at time 2791594
[LOG] Scheduler::TaskComplete(): Task 17 completed at 2791594 (target=11549910, delay=-8758316, SLA violated=NO)
[LOG] HandleTaskCompletion(): Task 21 completed at time 2821587
[LOG] Scheduler::TaskComplete(): Task 21 completed at 2821587 (target=11420427, delay=-8598840, SLA violated=NO)
[LOG] Scheduler::consolidateMachines(): Powering down idle machine 7 (active machines: 24)
[LOG] Scheduler::consolidateMachines(): Powering down idle machine 8 (active machines: 23)
[LOG] Scheduler::consolidateMachines(): Powering down idle machine 9 (active machines: 22)
[LOG] Scheduler::consolidateMachines(): Powering down idle machine 10 (active machines: 21)
[LOG] Scheduler::consolidateMachines(): Powering down idle machine 11 (active machines: 20)
[LOG] Scheduler::consolidateMachines(): Powering down idle machine 12 (active machines: 19)
[LOG] Scheduler::consolidateMachines(): Powering down idle machine 13 (active machines: 18)
[LOG] Scheduler::consolidateMachines(): Powering down idle machine 14 (active machines: 17)
[LOG] Scheduler::consolidateMachines(): Powering down idle machine 15 (active machines: 16)
[LOG] Scheduler::consolidateMachines(): Powering down idle machine 16 (active machines: 15)
[LOG] Scheduler::consolidateMachines(): Powering down idle machine 17 (active machines: 14)
[LOG] Scheduler::consolidateMachines(): Powering down idle machine 18 (active machines: 13)
[LOG] Scheduler::consolidateMachines(): Powering down idle machine 19 (active machines: 12)
[LOG] Scheduler::consolidateMachines(): Powering down idle machine 20 (active machines: 11)
[LOG] Scheduler::consolidateMachines(): Powering down idle machine 21 (active machines: 10)
[LOG] Scheduler::consolidateMachines(): Powering down idle machine 22 (active machines: 9)
[LOG] Scheduler::consolidateMachines(): Powering down idle machine 23 (active machines: 8)
[LOG] HandleTaskCompletion(): Task 20 completed at time 2924825
[LOG] Scheduler::TaskComplete(): Task 20 completed at 2924825 (target=11750652, delay=-8825827, SLA violated=NO)
[LOG] HandleTaskCompletion(): Task 18 completed at time 2934401
[LOG] Scheduler::TaskComplete(): Task 18 completed at 2934401 (target=11830422, delay=-8896021, SLA violated=NO)
[LOG] HandleNewTask(): Received new task 22 at time 2936168
[LOG] Scheduler::NewTask(): Task 22 requires VM=0 CPU=3 SLA=1 GPU=no Memory=8 TargetCompletion=11955084 Arrival=2936168
[DEBUG] Selected VM 0 with 0 active tasks on machine 0
[LOG] Scheduler::NewTask(): Task 22 placed on VM 17 (priority=0) VM now has 1 tasks, Machine 0 has 1 tasks, 16/16384 memory
[LOG] HandleNewTask(): Received new task 23 at time 2994099
[LOG] Scheduler::NewTask(): Task 23 requires VM=0 CPU=3 SLA=1 GPU=no Memory=8 TargetCompletion=12097555 Arrival=2994099
[DEBUG] Selected VM 0 with 0 active tasks on machine 0
[LOG] Scheduler::NewTask(): Task 23 placed on VM 18 (priority=0) VM now has 1 tasks, Machine 2 has 1 tasks, 16/16384 memory
[LOG] HandleTaskCompletion(): Task 22 completed at time 3275806
[LOG] Scheduler::TaskComplete(): Task 22 completed at 3275806 (target=11955084, delay=-8679278, SLA violated=NO)
[LOG] HandleTaskCompletion(): Task 23 completed at time 3361917
[LOG] Scheduler::TaskComplete(): Task 23 completed at 3361917 (target=12097555, delay=-8735638, SLA violated=NO)
[LOG] HandleNewTask(): Received new task 24 at time 3497128
[LOG] Scheduler::NewTask(): Task 24 requires VM=0 CPU=3 SLA=1 GPU=no Memory=8 TargetCompletion=12737182 Arrival=3497128
[DEBUG] Selected VM 0 with 0 active tasks on machine 0
[LOG] Scheduler::NewTask(): Task 24 placed on VM 19 (priority=0) VM now has 1 tasks, Machine 4 has 1 tasks, 16/16384 memory
[LOG] HandleNewTask(): Received new task 25 at time 3599522
[LOG] Scheduler::NewTask(): Task 25 requires VM=0 CPU=3 SLA=1 GPU=no Memory=8 TargetCompletion=12691743 Arrival=3599522
[DEBUG] Selected VM 0 with 0 active tasks on machine 0
[LOG] Scheduler::NewTask(): Task 25 placed on VM 20 (priority=0) VM now has 1 tasks, Machine 5 has 1 tasks, 16/16384 memory
[LOG] Scheduler::consolidateMachines(): Powering down idle machine 6 (active machines: 24)
[LOG] Scheduler::consolidateMachines(): Powering down idle machine 7 (active machines: 23)
[LOG] Scheduler::consolidateMachines(): Powering down idle machine 8 (active machines: 22)
[LOG] Scheduler::consolidateMachines(): Powering down idle machine 9 (active machines: 21)
[LOG] Scheduler::consolidateMachines(): Powering down idle machine 10 (active machines: 20)
[LOG] Scheduler::consolidateMachines(): Powering down idle machine 11 (active machines: 19)
[LOG] Scheduler::consolidateMachines(): Powering down idle machine 12 (active machines: 18)
[LOG] Scheduler::consolidateMachines(): Powering down idle machine 13 (active machines: 17)
[LOG] Scheduler::consolidateMachines(): Powering down idle machine 14 (active machines: 16)
[LOG] Scheduler::consolidateMachines(): Powering down idle machine 15 (active machines: 15)
[LOG] Scheduler::consolidateMachines(): Powering down idle machine 16 (active machines: 14)
[LOG] Scheduler::consolidateMachines(): Powering down idle machine 17 (active machines: 13)
[LOG] Scheduler::consolidateMachines(): Powering down idle machine 18 (active machines: 12)
[LOG] Scheduler::consolidateMachines(): Powering down idle machine 19 (active machines: 11)
[LOG] Scheduler::consolidateMachines(): Powering down idle machine 20 (active machines: 10)
[LOG] Scheduler::consolidateMachines(): Powering down idle machine 21 (active machines: 9)
[LOG] Scheduler::consolidateMachines(): Powering down idle machine 22 (active machines: 8)
[LOG] Scheduler::consolidateMachines(): Powering down idle machine 23 (active machines: 7)
[LOG] HandleNewTask(): Received new task 26 at time 3740240
[LOG] Scheduler::NewTask(): Task 26 requires VM=0 CPU=3 SLA=1 GPU=no Memory=8 TargetCompletion=12571222 Arrival=3740240
[DEBUG] Selected VM 0 with 0 active tasks on machine 0
[LOG] Scheduler::NewTask(): Task 26 placed on VM 21 (priority=0) VM now has 1 tasks, Machine 0 has 1 tasks, 16/16384 memory
[LOG] HandleNewTask(): Received new task 27 at time 3901055
[LOG] Scheduler::NewTask(): Task 27 requires VM=0 CPU=3 SLA=1 GPU=no Memory=8 TargetCompletion=13120766 Arrival=3901055
[DEBUG] Selected VM 0 with 0 active tasks on machine 0
[LOG] Scheduler::NewTask(): Task 27 placed on VM 22 (priority=0) VM now has 1 tasks, Machine 1 has 1 tasks, 16/16384 memory
[LOG] HandleNewTask(): Received new task 28 at time 3908948
[LOG] Scheduler::NewTask(): Task 28 requires VM=0 CPU=3 SLA=1 GPU=no Memory=8 TargetCompletion=13152700 Arrival=3908948
[DEBUG] Selected VM 0 with 0 active tasks on machine 0
[LOG] Scheduler::NewTask(): Task 28 placed on VM 23 (priority=0) VM now has 1 tasks, Machine 2 has 1 tasks, 16/16384 memory
[LOG] HandleTaskCompletion(): Task 24 completed at time 3910479
[LOG] Scheduler::TaskComplete(): Task 24 completed at 3910479 (target=12737182, delay=-8826703, SLA violated=NO)
[LOG] HandleTaskCompletion(): Task 25 completed at time 3963595
[LOG] Scheduler::TaskComplete(): Task 25 completed at 3963595 (target=12691743, delay=-8728148, SLA violated=NO)
[LOG] HandleTaskCompletion(): Task 26 completed at time 4017234
[LOG] Scheduler::TaskComplete(): Task 26 completed at 4017234 (target=12571222, delay=-8553988, SLA violated=NO)
[LOG] HandleNewTask(): Received new task 29 at time 4020679
[LOG] Scheduler::NewTask(): Task 29 requires VM=0 CPU=3 SLA=1 GPU=no Memory=8 TargetCompletion=13183604 Arrival=4020679
[DEBUG] Selected VM 0 with 0 active tasks on machine 0
[LOG] Scheduler::NewTask(): Task 29 placed on VM 24 (priority=0) VM now has 1 tasks, Machine 3 has 1 tasks, 16/16384 memory
[LOG] HandleNewTask(): Received new task 30 at time 4106066
[LOG] Scheduler::NewTask(): Task 30 requires VM=0 CPU=3 SLA=1 GPU=no Memory=8 TargetCompletion=13152185 Arrival=4106066
[DEBUG] Selected VM 0 with 0 active tasks on machine 0
[LOG] Scheduler::NewTask(): Task 30 placed on VM 25 (priority=0) VM now has 1 tasks, Machine 6 has 1 tasks, 16/16384 memory
[LOG] HandleNewTask(): Received new task 31 at time 4223782
[LOG] Scheduler::NewTask(): Task 31 requires VM=0 CPU=3 SLA=1 GPU=no Memory=8 TargetCompletion=13546293 Arrival=4223782
[DEBUG] Selected VM 0 with 0 active tasks on machine 0
[LOG] Scheduler::NewTask(): Task 31 placed on VM 26 (priority=0) VM now has 1 tasks, Machine 7 has 1 tasks, 16/16384 memory
[LOG] HandleTaskCompletion(): Task 27 completed at time 4307625
[LOG] Scheduler::TaskComplete(): Task 27 completed at 4307625 (target=13120766, delay=-8813141, SLA violated=NO)
[LOG] HandleTaskCompletion(): Task 28 completed at time 4323532
[LOG] Scheduler::TaskComplete(): Task 28 completed at 4323532 (target=13152700, delay=-8829168, SLA violated=NO)
[LOG] HandleTaskCompletion(): Task 29 completed at time 4408320
[LOG] Scheduler::TaskComplete(): Task 29 completed at 4408320 (target=13183604, delay=-8775284, SLA violated=NO)
[LOG] Scheduler::consolidateMachines(): Powering down idle machine 8 (active machines: 24)
[LOG] Scheduler::consolidateMachines(): Powering down idle machine 9 (active machines: 23)
[LOG] Scheduler::consolidateMachines(): Powering down idle machine 10 (active machines: 22)
[LOG] Scheduler::consolidateMachines(): Powering down idle machine 11 (active machines: 21)
[LOG] Scheduler::consolidateMachines(): Powering down idle machine 12 (active machines: 20)
[LOG] Scheduler::consolidateMachines(): Powering down idle machine 13 (active machines: 19)
[LOG] Scheduler::consolidateMachines(): Powering down idle machine 14 (active machines: 18)
[LOG] Scheduler::consolidateMachines(): Powering down idle machine 15 (active machines: 17)
[LOG] Scheduler::consolidateMachines(): Powering down idle machine 16 (active machines: 16)
[LOG] Scheduler::consolidateMachines(): Powering down idle machine 17 (active machines: 15)
[LOG] Scheduler::consolidateMachines(): Powering down idle machine 18 (active machines: 14)
[LOG] Scheduler::consolidateMachines(): Powering down idle machine 19 (active machines: 13)
[LOG] Scheduler::consolidateMachines(): Powering down idle machine 20 (active machines: 12)
[LOG] Scheduler::consolidateMachines(): Powering down idle machine 21 (active machines: 11)
[LOG] Scheduler::consolidateMachines(): Powering down idle machine 22 (active machines: 10)
[LOG] Scheduler::consolidateMachines(): Powering down idle machine 23 (active machines: 9)
[LOG] HandleTaskCompletion(): Task 30 completed at time 4454772
[LOG] Scheduler::TaskComplete(): Task 30 completed at 4454772 (target=13152185, delay=-8697413, SLA violated=NO)
[LOG] HandleNewTask(): Received new task 32 at time 4523518
[LOG] Scheduler::NewTask(): Task 32 requires VM=0 CPU=3 SLA=1 GPU=no Memory=8 TargetCompletion=13681365 Arrival=4523518
[DEBUG] Selected VM 0 with 0 active tasks on machine 0
[LOG] Scheduler::NewTask(): Task 32 placed on VM 27 (priority=0) VM now has 1 tasks, Machine 0 has 1 tasks, 16/16384 memory
[LOG] HandleNewTask(): Received new task 33 at time 4599548
[LOG] Scheduler::NewTask(): Task 33 requires VM=0 CPU=3 SLA=1 GPU=no Memory=8 TargetCompletion=13628998 Arrival=4599548
[DEBUG] Selected VM 0 with 0 active tasks on machine 0
[LOG] Scheduler::NewTask(): Task 33 placed on VM 28 (priority=0) VM now has 1 tasks, Machine 1 has 1 tasks, 16/16384 memory
[LOG] HandleTaskCompletion(): Task 31 completed at time 4664619
[LOG] Scheduler::TaskComplete(): Task 31 completed at 4664619 (target=13546293, delay=-8881674, SLA violated=NO)
[LOG] Scheduler::consolidateMachines(): Powering down idle machine 2 (active machines: 24)
[LOG] Scheduler::consolidateMachines(): Powering down idle machine 3 (active machines: 23)
[LOG] Scheduler::consolidateMachines(): Powering down idle machine 4 (active machines: 22)
[LOG] Scheduler::consolidateMachines(): Powering down idle machine 5 (active machines: 21)
[LOG] Scheduler::consolidateMachines(): Powering down idle machine 8 (active machines: 20)
[LOG] Scheduler::consolidateMachines(): Powering down idle machine 9 (active machines: 19)
[LOG] Scheduler::consolidateMachines(): Powering down idle machine 10 (active machines: 18)
[LOG] Scheduler::consolidateMachines(): Powering down idle machine 11 (active machines: 17)
[LOG] Scheduler::consolidateMachines(): Powering down idle machine 12 (active machines: 16)
[LOG] Scheduler::consolidateMachines(): Powering down idle machine 13 (active machines: 15)
[LOG] Scheduler::consolidateMachines(): Powering down idle machine 14 (active machines: 14)
[LOG] Scheduler::consolidateMachines(): Powering down idle machine 15 (active machines: 13)
[LOG] Scheduler::consolidateMachines(): Powering down idle machine 16 (active machines: 12)
[LOG] Scheduler::consolidateMachines(): Powering down idle machine 17 (active machines: 11)
[LOG] Scheduler::consolidateMachines(): Powering down idle machine 18 (active machines: 10)
[LOG] Scheduler::consolidateMachines(): Powering down idle machine 19 (active machines: 9)
[LOG] Scheduler::consolidateMachines(): Powering down idle machine 20 (active machines: 8)
[LOG] Scheduler::consolidateMachines(): Powering down idle machine 21 (active machines: 7)
[LOG] Scheduler::consolidateMachines(): Powering down idle machine 22 (active machines: 6)
[LOG] Scheduler::consolidateMachines(): Powering down idle machine 23 (active machines: 5)
[LOG] HandleTaskCompletion(): Task 32 completed at time 4909467
[LOG] Scheduler::TaskComplete(): Task 32 completed at 4909467 (target=13681365, delay=-8771898, SLA violated=NO)
[LOG] HandleTaskCompletion(): Task 33 completed at time 4942698
[LOG] Scheduler::TaskComplete(): Task 33 completed at 4942698 (target=13628998, delay=-8686300, SLA violated=NO)
[LOG] HandleNewTask(): Received new task 82 at time 5003061
[LOG] Scheduler::NewTask(): Task 82 requires VM=0 CPU=3 SLA=0 GPU=no Memory=8 TargetCompletion=29568769 Arrival=5003061
[DEBUG] Selected VM 0 with 0 active tasks on machine 0
[LOG] Scheduler::NewTask(): Task 82 placed on VM 29 (priority=0) VM now has 1 tasks, Machine 2 has 1 tasks, 16/16384 memory
[LOG] HandleNewTask(): Received new task 83 at time 5004086
[LOG] Scheduler::NewTask(): Task 83 requires VM=0 CPU=3 SLA=0 GPU=no Memory=8 TargetCompletion=27075463 Arrival=5004086
[DEBUG] Selected VM 0 with 0 active tasks on machine 0
[LOG] Scheduler::NewTask(): Task 83 placed on VM 30 (priority=0) VM now has 1 tasks, Machine 3 has 1 tasks, 16/16384 memory
[LOG] HandleNewTask(): Received new task 84 at time 5005691
[LOG] Scheduler::NewTask(): Task 84 requires VM=0 CPU=3 SLA=0 GPU=no Memory=8 TargetCompletion=26959910 Arrival=5005691
[DEBUG] Selected VM 0 with 0 active tasks on machine 0
[LOG] Scheduler::NewTask(): Task 84 placed on VM 31 (priority=0) VM now has 1 tasks, Machine 4 has 1 tasks, 16/16384 memory
[LOG] HandleNewTask(): Received new task 85 at time 5006149
[LOG] Scheduler::NewTask(): Task 85 requires VM=0 CPU=3 SLA=0 GPU=no Memory=8 TargetCompletion=29765391 Arrival=5006149
[DEBUG] Selected VM 0 with 0 active tasks on machine 0
[LOG] Scheduler::NewTask(): Task 85 placed on VM 32 (priority=0) VM now has 1 tasks, Machine 5 has 1 tasks, 16/16384 memory
[LOG] HandleNewTask(): Received new task 86 at time 5006304
[LOG] Scheduler::NewTask(): Task 86 requires VM=0 CPU=3 SLA=0 GPU=no Memory=8 TargetCompletion=28957046 Arrival=5006304
[DEBUG] Selected VM 0 with 0 active tasks on machine 0
[LOG] Scheduler::NewTask(): Task 86 placed on VM 33 (priority=0) VM now has 1 tasks, Machine 6 has 1 tasks, 16/16384 memory
[LOG] HandleNewTask(): Received new task 87 at time 5006827
[LOG] Scheduler::NewTask(): Task 87 requires VM=0 CPU=3 SLA=0 GPU=no Memory=8 TargetCompletion=29467394 Arrival=5006827
[DEBUG] Selected VM 0 with 0 active tasks on machine 0
[LOG] Scheduler::NewTask(): Task 87 placed on VM 34 (priority=0) VM now has 1 tasks, Machine 7 has 1 tasks, 16/16384 memory
[LOG] HandleNewTask(): Received new task 88 at time 5009850
[LOG] Scheduler::NewTask(): Task 88 requires VM=0 CPU=3 SLA=0 GPU=no Memory=8 TargetCompletion=27826838 Arrival=5009850
[DEBUG] Selected VM 0 with 0 active tasks on machine 0
[LOG] Scheduler::NewTask(): Task 88 placed on VM 35 (priority=0) VM now has 1 tasks, Machine 8 has 1 tasks, 16/16384 memory
[LOG] HandleNewTask(): Received new task 89 at time 5009997
[LOG] Scheduler::NewTask(): Task 89 requires VM=0 CPU=3 SLA=0 GPU=no Memory=8 TargetCompletion=30811045 Arrival=5009997
[DEBUG] Selected VM 0 with 0 active tasks on machine 0
[LOG] Scheduler::NewTask(): Task 89 placed on VM 36 (priority=0) VM now has 1 tasks, Machine 9 has 1 tasks, 16/16384 memory
[LOG] HandleNewTask(): Received new task 90 at time 5010332
[LOG] Scheduler::NewTask(): Task 90 requires VM=0 CPU=3 SLA=0 GPU=no Memory=8 TargetCompletion=28692139 Arrival=5010332
[DEBUG] Selected VM 0 with 0 active tasks on machine 0
[LOG] Scheduler::NewTask(): Task 90 placed on VM 37 (priority=0) VM now has 1 tasks, Machine 10 has 1 tasks, 16/16384 memory
[LOG] HandleNewTask(): Received new task 91 at time 5010412
[LOG] Scheduler::NewTask(): Task 91 requires VM=0 CPU=3 SLA=0 GPU=no Memory=8 TargetCompletion=28162465 Arrival=5010412
[DEBUG] Selected VM 0 with 0 active tasks on machine 0
[LOG] Scheduler::NewTask(): Task 91 placed on VM 38 (priority=0) VM now has 1 tasks, Machine 11 has 1 tasks, 16/16384 memory
[LOG] HandleNewTask(): Received new task 92 at time 5011110
[LOG] Scheduler::NewTask(): Task 92 requires VM=0 CPU=3 SLA=0 GPU=no Memory=8 TargetCompletion=27876022 Arrival=5011110
[DEBUG] Selected VM 0 with 0 active tasks on machine 0
[LOG] Scheduler::NewTask(): Task 92 placed on VM 39 (priority=0) VM now has 1 tasks, Machine 12 has 1 tasks, 16/16384 memory
[LOG] HandleNewTask(): Received new task 93 at time 5014476
[LOG] Scheduler::NewTask(): Task 93 requires VM=0 CPU=3 SLA=0 GPU=no Memory=8 TargetCompletion=27722329 Arrival=5014476
[DEBUG] Selected VM 0 with 0 active tasks on machine 0
[LOG] Scheduler::NewTask(): Task 93 placed on VM 40 (priority=0) VM now has 1 tasks, Machine 13 has 1 tasks, 16/16384 memory
[LOG] HandleNewTask(): Received new task 94 at time 5017985
[LOG] Scheduler::NewTask(): Task 94 requires VM=0 CPU=3 SLA=0 GPU=no Memory=8 TargetCompletion=27011159 Arrival=5017985
[DEBUG] Selected VM 0 with 0 active tasks on machine 0
[LOG] Scheduler::NewTask(): Task 94 placed on VM 41 (priority=0) VM now has 1 tasks, Machine 14 has 1 tasks, 16/16384 memory
[LOG] HandleNewTask(): Received new task 95 at time 5018872
[LOG] Scheduler::NewTask(): Task 95 requires VM=0 CPU=3 SLA=0 GPU=no Memory=8 TargetCompletion=27011386 Arrival=5018872
[DEBUG] Selected VM 0 with 0 active tasks on machine 0
[LOG] Scheduler::NewTask(): Task 95 placed on VM 42 (priority=0) VM now has 1 tasks, Machine 15 has 1 tasks, 16/16384 memory
[LOG] HandleNewTask(): Received new task 96 at time 5019121
[LOG] Scheduler::NewTask(): Task 96 requires VM=0 CPU=3 SLA=0 GPU=no Memory=8 TargetCompletion=30298995 Arrival=5019121
[DEBUG] Selected VM 0 with 0 active tasks on machine 0
[LOG] Scheduler::NewTask(): Task 96 placed on VM 43 (priority=0) VM now has 1 tasks, Machine 0 has 1 tasks, 24/16384 memory
[LOG] HandleNewTask(): Received new task 97 at time 5019510
[LOG] Scheduler::NewTask(): Task 97 requires VM=0 CPU=3 SLA=0 GPU=no Memory=8 TargetCompletion=29098658 Arrival=5019510
[DEBUG] Selected VM 0 with 0 active tasks on machine 0
[LOG] Scheduler::NewTask(): Task 97 placed on VM 44 (priority=0) VM now has 1 tasks, Machine 1 has 1 tasks, 24/16384 memory
[LOG] HandleNewTask(): Received new task 98 at time 5020868
[LOG] Scheduler::NewTask(): Task 98 requires VM=0 CPU=3 SLA=0 GPU=no Memory=8 TargetCompletion=28726687 Arrival=5020868
[DEBUG] Selected VM 0 with 0 active tasks on machine 0
[LOG] Scheduler::NewTask(): Task 98 placed on VM 45 (priority=0) VM now has 1 tasks, Machine 2 has 2 tasks, 32/16384 memory
[LOG] HandleNewTask(): Received new task 99 at time 5022616
[LOG] Scheduler::NewTask(): Task 99 requires VM=0 CPU=3 SLA=0 GPU=no Memory=8 TargetCompletion=27889252 Arrival=5022616
[DEBUG] Selected VM 0 with 0 active tasks on machine 0
[LOG] Scheduler::NewTask(): Task 99 placed on VM 46 (priority=0) VM now has 1 tasks, Machine 3 has 2 tasks, 32/16384 memory
[LOG] HandleNewTask(): Received new task 100 at time 5023892
[LOG] Scheduler::NewTask(): Task 100 requires VM=0 CPU=3 SLA=0 GPU=no Memory=8 TargetCompletion=30460112 Arrival=5023892
[DEBUG] Selected VM 0 with 0 active tasks on machine 0
[LOG] Scheduler::NewTask(): Task 100 placed on VM 47 (priority=0) VM now has 1 tasks, Machine 4 has 2 tasks, 32/16384 memory
[LOG] HandleNewTask(): Received new task 101 at time 5024396
[LOG] Scheduler::NewTask(): Task 101 requires VM=0 CPU=3 SLA=0 GPU=no Memory=8 TargetCompletion=27374635 Arrival=5024396
[DEBUG] Selected VM 0 with 0 active tasks on machine 0
[LOG] Scheduler::NewTask(): Task 101 placed on VM 48 (priority=0) VM now has 1 tasks, Machine 5 has 2 tasks, 32/16384 memory
[LOG] HandleNewTask(): Received new task 102 at time 5024701
[LOG] Scheduler::NewTask(): Task 102 requires VM=0 CPU=3 SLA=0 GPU=no Memory=8 TargetCompletion=28589425 Arrival=5024701
[DEBUG] Selected VM 0 with 0 active tasks on machine 0
[LOG] Scheduler::NewTask(): Task 102 placed on VM 49 (priority=0) VM now has 1 tasks, Machine 6 has 2 tasks, 32/16384 memory
[LOG] HandleNewTask(): Received new task 103 at time 5026413
[LOG] Scheduler::NewTask(): Task 103 requires VM=0 CPU=3 SLA=0 GPU=no Memory=8 TargetCompletion=28630672 Arrival=5026413
[DEBUG] Selected VM 0 with 0 active tasks on machine 0
[LOG] Scheduler::NewTask(): Task 103 placed on VM 50 (priority=0) VM now has 1 tasks, Machine 7 has 2 tasks, 32/16384 memory
[LOG] HandleNewTask(): Received new task 104 at time 5026989
[LOG] Scheduler::NewTask(): Task 104 requires VM=0 CPU=3 SLA=0 GPU=no Memory=8 TargetCompletion=28329473 Arrival=5026989
[DEBUG] Selected VM 0 with 0 active tasks on machine 0
[LOG] Scheduler::NewTask(): Task 104 placed on VM 51 (priority=0) VM now has 1 tasks, Machine 8 has 2 tasks, 32/16384 memory
[LOG] HandleNewTask(): Received new task 105 at time 5027827
[LOG] Scheduler::NewTask(): Task 105 requires VM=0 CPU=3 SLA=0 GPU=no Memory=8 TargetCompletion=27145755 Arrival=5027827
[DEBUG] Selected VM 0 with 0 active tasks on machine 0
[LOG] Scheduler::NewTask(): Task 105 placed on VM 52 (priority=0) VM now has 1 tasks, Machine 9 has 2 tasks, 32/16384 memory
[LOG] HandleNewTask(): Received new task 106 at time 5028134
[LOG] Scheduler::NewTask(): Task 106 requires VM=0 CPU=3 SLA=0 GPU=no Memory=8 TargetCompletion=28253203 Arrival=5028134
[DEBUG] Selected VM 0 with 0 active tasks on machine 0
[LOG] Scheduler::NewTask(): Task 106 placed on VM 53 (priority=0) VM now has 1 tasks, Machine 10 has 2 tasks, 32/16384 memory
[LOG] HandleNewTask(): Received new task 107 at time 5030966
[LOG] Scheduler::NewTask(): Task 107 requires VM=0 CPU=3 SLA=0 GPU=no Memory=8 TargetCompletion=29903362 Arrival=5030966
[DEBUG] Selected VM 0 with 0 active tasks on machine 0
[LOG] Scheduler::NewTask(): Task 107 placed on VM 54 (priority=0) VM now has 1 tasks, Machine 11 has 2 tasks, 32/16384 memory
[LOG] HandleNewTask(): Received new task 108 at time 5032757
[LOG] Scheduler::NewTask(): Task 108 requires VM=0 CPU=3 SLA=0 GPU=no Memory=8 TargetCompletion=29630167 Arrival=5032757
[DEBUG] Selected VM 0 with 0 active tasks on machine 0
[LOG] Scheduler::NewTask(): Task 108 placed on VM 55 (priority=0) VM now has 1 tasks, Machine 12 has 2 tasks, 32/16384 memory
[LOG] HandleNewTask(): Received new task 109 at time 5034060
[LOG] Scheduler::NewTask(): Task 109 requires VM=0 CPU=3 SLA=0 GPU=no Memory=8 TargetCompletion=30902970 Arrival=5034060
[DEBUG] Selected VM 0 with 0 active tasks on machine 0
[LOG] Scheduler::NewTask(): Task 109 placed on VM 56 (priority=0) VM now has 1 tasks, Machine 13 has 2 tasks, 32/16384 memory
[LOG] HandleNewTask(): Received new task 110 at time 5034614
[LOG] Scheduler::NewTask(): Task 110 requires VM=0 CPU=3 SLA=0 GPU=no Memory=8 TargetCompletion=30930440 Arrival=5034614
[DEBUG] Selected VM 0 with 0 active tasks on machine 0
[LOG] Scheduler::NewTask(): Task 110 placed on VM 57 (priority=0) VM now has 1 tasks, Machine 14 has 2 tasks, 32/16384 memory
[LOG] HandleNewTask(): Received new task 111 at time 5036000
[LOG] Scheduler::NewTask(): Task 111 requires VM=0 CPU=3 SLA=0 GPU=no Memory=8 TargetCompletion=30269728 Arrival=5036000
[DEBUG] Selected VM 0 with 0 active tasks on machine 0
[LOG] Scheduler::NewTask(): Task 111 placed on VM 58 (priority=0) VM now has 1 tasks, Machine 15 has 2 tasks, 32/16384 memory
[LOG] HandleNewTask(): Received new task 112 at time 5037358
[LOG] Scheduler::NewTask(): Task 112 requires VM=0 CPU=3 SLA=0 GPU=no Memory=8 TargetCompletion=27449823 Arrival=5037358
[DEBUG] Selected VM 0 with 0 active tasks on machine 0
[LOG] Scheduler::NewTask(): Task 112 placed on VM 59 (priority=0) VM now has 1 tasks, Machine 0 has 2 tasks, 40/16384 memory
[LOG] HandleNewTask(): Received new task 113 at time 5038809
[LOG] Scheduler::NewTask(): Task 113 requires VM=0 CPU=3 SLA=0 GPU=no Memory=8 TargetCompletion=29332632 Arrival=5038809
[DEBUG] Selected VM 0 with 0 active tasks on machine 0
[LOG] Scheduler::NewTask(): Task 113 placed on VM 60 (priority=0) VM now has 1 tasks, Machine 1 has 2 tasks, 40/16384 memory
[LOG] HandleNewTask(): Received new task 114 at time 5039976
[LOG] Scheduler::NewTask(): Task 114 requires VM=0 CPU=3 SLA=0 GPU=no Memory=8 TargetCompletion=27959410 Arrival=5039976
[DEBUG] Selected VM 0 with 0 active tasks on machine 0
[LOG] Scheduler::NewTask(): Task 114 placed on VM 61 (priority=0) VM now has 1 tasks, Machine 2 has 3 tasks, 48/16384 memory
[LOG] HandleNewTask(): Received new task 115 at time 5041520
[LOG] Scheduler::NewTask(): Task 115 requires VM=0 CPU=3 SLA=0 GPU=no Memory=8 TargetCompletion=30985924 Arrival=5041520
[DEBUG] Selected VM 0 with 0 active tasks on machine 0
[LOG] Scheduler::NewTask(): Task 115 placed on VM 62 (priority=0) VM now has 1 tasks, Machine 3 has 3 tasks, 48/16384 memory
[LOG] HandleNewTask(): Received new task 116 at time 5041897
[LOG] Scheduler::NewTask(): Task 116 requires VM=0 CPU=3 SLA=0 GPU=no Memory=8 TargetCompletion=26970632 Arrival=5041897
[DEBUG] Selected VM 0 with 0 active tasks on machine 0
[LOG] Scheduler::NewTask(): Task 116 placed on VM 63 (priority=0) VM now has 1 tasks, Machine 4 has 3 tasks, 48/16384 memory
[LOG] HandleTaskCompletion(): Task 101 completed at time 5042819
[LOG] Scheduler::TaskComplete(): Task 101 completed at 5042819 (target=27374635, delay=-22331816, SLA violated=NO)
[LOG] HandleNewTask(): Received new task 117 at time 5043811
[LOG] Scheduler::NewTask(): Task 117 requires VM=0 CPU=3 SLA=0 GPU=no Memory=8 TargetCompletion=29426833 Arrival=5043811
[DEBUG] Selected VM 0 with 0 active tasks on machine 0
[LOG] Scheduler::NewTask(): Task 117 placed on VM 64 (priority=0) VM now has 1 tasks, Machine 5 has 2 tasks, 40/16384 memory
[LOG] HandleNewTask(): Received new task 118 at time 5043842
[LOG] Scheduler::NewTask(): Task 118 requires VM=0 CPU=3 SLA=0 GPU=no Memory=8 TargetCompletion=30675221 Arrival=5043842
[DEBUG] Selected VM 0 with 0 active tasks on machine 0
[LOG] Scheduler::NewTask(): Task 118 placed on VM 65 (priority=0) VM now has 1 tasks, Machine 6 has 3 tasks, 48/16384 memory
[LOG] HandleNewTask(): Received new task 119 at time 5044444
[LOG] Scheduler::NewTask(): Task 119 requires VM=0 CPU=3 SLA=0 GPU=no Memory=8 TargetCompletion=31098112 Arrival=5044444
[DEBUG] Selected VM 0 with 0 active tasks on machine 0
[LOG] Scheduler::NewTask(): Task 119 placed on VM 66 (priority=0) VM now has 1 tasks, Machine 7 has 3 tasks, 48/16384 memory
[LOG] HandleNewTask(): Received new task 120 at time 5047954
[LOG] Scheduler::NewTask(): Task 120 requires VM=0 CPU=3 SLA=0 GPU=no Memory=8 TargetCompletion=28657048 Arrival=5047954
[DEBUG] Selected VM 0 with 0 active tasks on machine 0
[LOG] Scheduler::NewTask(): Task 120 placed on VM 67 (priority=0) VM now has 1 tasks, Machine 8 has 3 tasks, 48/16384 memory
[LOG] HandleNewTask(): Received new task 121 at time 5049306
[LOG] Scheduler::NewTask(): Task 121 requires VM=0 CPU=3 SLA=0 GPU=no Memory=8 TargetCompletion=30927137 Arrival=5049306
[DEBUG] Selected VM 0 with 0 active tasks on machine 0
[LOG] Scheduler::NewTask(): Task 121 placed on VM 68 (priority=0) VM now has 1 tasks, Machine 9 has 3 tasks, 48/16384 memory
[LOG] HandleNewTask(): Received new task 122 at time 5049325
[LOG] Scheduler::NewTask(): Task 122 requires VM=0 CPU=3 SLA=0 GPU=no Memory=8 TargetCompletion=29068873 Arrival=5049325
[DEBUG] Selected VM 0 with 0 active tasks on machine 0
[LOG] Scheduler::NewTask(): Task 122 placed on VM 69 (priority=0) VM now has 1 tasks, Machine 10 has 3 tasks, 48/16384 memory
[LOG] HandleNewTask(): Received new task 123 at time 5050778
[LOG] Scheduler::NewTask(): Task 123 requires VM=0 CPU=3 SLA=0 GPU=no Memory=8 TargetCompletion=29096281 Arrival=5050778
[DEBUG] Selected VM 0 with 0 active tasks on machine 0
[LOG] Scheduler::NewTask(): Task 123 placed on VM 70 (priority=0) VM now has 1 tasks, Machine 11 has 3 tasks, 48/16384 memory
[LOG] HandleNewTask(): Received new task 124 at time 5052075
[LOG] Scheduler::NewTask(): Task 124 requires VM=0 CPU=3 SLA=0 GPU=no Memory=8 TargetCompletion=27140611 Arrival=5052075
[DEBUG] Selected VM 0 with 0 active tasks on machine 0
[LOG] Scheduler::NewTask(): Task 124 placed on VM 71 (priority=0) VM now has 1 tasks, Machine 12 has 3 tasks, 48/16384 memory
[LOG] HandleNewTask(): Received new task 125 at time 5052362
[LOG] Scheduler::NewTask(): Task 125 requires VM=0 CPU=3 SLA=0 GPU=no Memory=8 TargetCompletion=28279424 Arrival=5052362
[DEBUG] Selected VM 0 with 0 active tasks on machine 0
[LOG] Scheduler::NewTask(): Task 125 placed on VM 72 (priority=0) VM now has 1 tasks, Machine 13 has 3 tasks, 48/16384 memory
[LOG] HandleNewTask(): Received new task 126 at time 5052598
[LOG] Scheduler::NewTask(): Task 126 requires VM=0 CPU=3 SLA=0 GPU=no Memory=8 TargetCompletion=27207469 Arrival=5052598
[DEBUG] Selected VM 0 with 0 active tasks on machine 0
[LOG] Scheduler::NewTask(): Task 126 placed on VM 73 (priority=0) VM now has 1 tasks, Machine 14 has 3 tasks, 48/16384 memory
[LOG] HandleNewTask(): Received new task 127 at time 5052658
[LOG] Scheduler::NewTask(): Task 127 requires VM=0 CPU=3 SLA=0 GPU=no Memory=8 TargetCompletion=27344224 Arrival=5052658
[DEBUG] Selected VM 0 with 0 active tasks on machine 0
[LOG] Scheduler::NewTask(): Task 127 placed on VM 74 (priority=0) VM now has 1 tasks, Machine 15 has 3 tasks, 48/16384 memory
[LOG] HandleNewTask(): Received new task 128 at time 5053022
[LOG] Scheduler::NewTask(): Task 128 requires VM=0 CPU=3 SLA=0 GPU=no Memory=8 TargetCompletion=30279929 Arrival=5053022
[DEBUG] Selected VM 0 with 0 active tasks on machine 0
[LOG] Scheduler::NewTask(): Task 128 placed on VM 75 (priority=0) VM now has 1 tasks, Machine 0 has 3 tasks, 56/16384 memory
[LOG] HandleNewTask(): Received new task 129 at time 5054973
[LOG] Scheduler::NewTask(): Task 129 requires VM=0 CPU=3 SLA=0 GPU=no Memory=8 TargetCompletion=27863955 Arrival=5054973
[DEBUG] Selected VM 0 with 0 active tasks on machine 0
[LOG] Scheduler::NewTask(): Task 129 placed on VM 76 (priority=0) VM now has 1 tasks, Machine 1 has 3 tasks, 56/16384 memory
[LOG] HandleNewTask(): Received new task 130 at time 5058211
[LOG] Scheduler::NewTask(): Task 130 requires VM=0 CPU=3 SLA=0 GPU=no Memory=8 TargetCompletion=27799132 Arrival=5058211
[DEBUG] Selected VM 0 with 0 active tasks on machine 0
[LOG] Scheduler::NewTask(): Task 130 placed on VM 77 (priority=0) VM now has 1 tasks, Machine 5 has 3 tasks, 56/16384 memory
[LOG] HandleNewTask(): Received new task 131 at time 5058236
[LOG] Scheduler::NewTask(): Task 131 requires VM=0 CPU=3 SLA=0 GPU=no Memory=8 TargetCompletion=30231559 Arrival=5058236
[DEBUG] Selected VM 0 with 0 active tasks on machine 0
[LOG] Scheduler::NewTask(): Task 131 placed on VM 78 (priority=0) VM now has 1 tasks, Machine 2 has 4 tasks, 64/16384 memory
[LOG] HandleNewTask(): Received new task 132 at time 5058418
[LOG] Scheduler::NewTask(): Task 132 requires VM=0 CPU=3 SLA=0 GPU=no Memory=8 TargetCompletion=27436487 Arrival=5058418
[DEBUG] Selected VM 0 with 0 active tasks on machine 0
[LOG] Scheduler::NewTask(): Task 132 placed on VM 79 (priority=0) VM now has 1 tasks, Machine 3 has 4 tasks, 64/16384 memory
[LOG] HandleNewTask(): Received new task 133 at time 5060889
[LOG] Scheduler::NewTask(): Task 133 requires VM=0 CPU=3 SLA=0 GPU=no Memory=8 TargetCompletion=28179865 Arrival=5060889
[DEBUG] Selected VM 0 with 0 active tasks on machine 0
[LOG] Scheduler::NewTask(): Task 133 placed on VM 80 (priority=0) VM now has 1 tasks, Machine 4 has 4 tasks, 64/16384 memory
[LOG] HandleNewTask(): Received new task 134 at time 5061829
[LOG] Scheduler::NewTask(): Task 134 requires VM=0 CPU=3 SLA=0 GPU=no Memory=8 TargetCompletion=27037802 Arrival=5061829
[DEBUG] Selected VM 0 with 0 active tasks on machine 0
[LOG] Scheduler::NewTask(): Task 134 placed on VM 81 (priority=0) VM now has 1 tasks, Machine 6 has 4 tasks, 64/16384 memory
[LOG] HandleNewTask(): Received new task 135 at time 5062119
[LOG] Scheduler::NewTask(): Task 135 requires VM=0 CPU=3 SLA=0 GPU=no Memory=8 TargetCompletion=30525655 Arrival=5062119
[DEBUG] Selected VM 0 with 0 active tasks on machine 0
[LOG] Scheduler::NewTask(): Task 135 placed on VM 82 (priority=0) VM now has 1 tasks, Machine 7 has 4 tasks, 64/16384 memory
[LOG] HandleNewTask(): Received new task 136 at time 5063792
[LOG] Scheduler::NewTask(): Task 136 requires VM=0 CPU=3 SLA=0 GPU=no Memory=8 TargetCompletion=29148883 Arrival=5063792
[DEBUG] Selected VM 0 with 0 active tasks on machine 0
[LOG] Scheduler::NewTask(): Task 136 placed on VM 83 (priority=0) VM now has 1 tasks, Machine 8 has 4 tasks, 64/16384 memory
[LOG] HandleNewTask(): Received new task 137 at time 5063909
[LOG] Scheduler::NewTask(): Task 137 requires VM=0 CPU=3 SLA=0 GPU=no Memory=8 TargetCompletion=30870053 Arrival=5063909
[DEBUG] Selected VM 0 with 0 active tasks on machine 0
[LOG] Scheduler::NewTask(): Task 137 placed on VM 84 (priority=0) VM now has 1 tasks, Machine 9 has 4 tasks, 64/16384 memory
[LOG] HandleNewTask(): Received new task 138 at time 5064238
[LOG] Scheduler::NewTask(): Task 138 requires VM=0 CPU=3 SLA=0 GPU=no Memory=8 TargetCompletion=28302432 Arrival=5064238
[DEBUG] Selected VM 0 with 0 active tasks on machine 0
[LOG] Scheduler::NewTask(): Task 138 placed on VM 85 (priority=0) VM now has 1 tasks, Machine 10 has 4 tasks, 64/16384 memory
[LOG] HandleNewTask(): Received new task 139 at time 5067912
[LOG] Scheduler::NewTask(): Task 139 requires VM=0 CPU=3 SLA=0 GPU=no Memory=8 TargetCompletion=29313126 Arrival=5067912
[DEBUG] Selected VM 0 with 0 active tasks on machine 0
[LOG] Scheduler::NewTask(): Task 139 placed on VM 86 (priority=0) VM now has 1 tasks, Machine 11 has 4 tasks, 64/16384 memory
[LOG] HandleNewTask(): Received new task 140 at time 5070231
[LOG] Scheduler::NewTask(): Task 140 requires VM=0 CPU=3 SLA=0 GPU=no Memory=8 TargetCompletion=27964408 Arrival=5070231
[DEBUG] Selected VM 0 with 0 active tasks on machine 0
[LOG] Scheduler::NewTask(): Task 140 placed on VM 87 (priority=0) VM now has 1 tasks, Machine 12 has 4 tasks, 64/16384 memory
[LOG] HandleNewTask(): Received new task 141 at time 5070721
[LOG] Scheduler::NewTask(): Task 141 requires VM=0 CPU=3 SLA=0 GPU=no Memory=8 TargetCompletion=29821273 Arrival=5070721
[DEBUG] Selected VM 0 with 0 active tasks on machine 0
[LOG] Scheduler::NewTask(): Task 141 placed on VM 88 (priority=0) VM now has 1 tasks, Machine 13 has 4 tasks, 64/16384 memory
[LOG] HandleNewTask(): Received new task 142 at time 5071951
[LOG] Scheduler::NewTask(): Task 142 requires VM=0 CPU=3 SLA=0 GPU=no Memory=8 TargetCompletion=28015056 Arrival=5071951
[DEBUG] Selected VM 0 with 0 active tasks on machine 0
[LOG] Scheduler::NewTask(): Task 142 placed on VM 89 (priority=0) VM now has 1 tasks, Machine 14 has 4 tasks, 64/16384 memory
[LOG] HandleNewTask(): Received new task 143 at time 5073616
[LOG] Scheduler::NewTask(): Task 143 requires VM=0 CPU=3 SLA=0 GPU=no Memory=8 TargetCompletion=27927394 Arrival=5073616
[DEBUG] Selected VM 0 with 0 active tasks on machine 0
[LOG] Scheduler::NewTask(): Task 143 placed on VM 90 (priority=0) VM now has 1 tasks, Machine 15 has 4 tasks, 64/16384 memory
[LOG] HandleNewTask(): Received new task 144 at time 5075534
[LOG] Scheduler::NewTask(): Task 144 requires VM=0 CPU=3 SLA=0 GPU=no Memory=8 TargetCompletion=28150817 Arrival=5075534
[DEBUG] Selected VM 0 with 0 active tasks on machine 0
[LOG] Scheduler::NewTask(): Task 144 placed on VM 91 (priority=0) VM now has 1 tasks, Machine 0 has 4 tasks, 72/16384 memory
[LOG] HandleNewTask(): Received new task 145 at time 5076284
[LOG] Scheduler::NewTask(): Task 145 requires VM=0 CPU=3 SLA=0 GPU=no Memory=8 TargetCompletion=27901431 Arrival=5076284
[DEBUG] Selected VM 0 with 0 active tasks on machine 0
[LOG] Scheduler::NewTask(): Task 145 placed on VM 92 (priority=0) VM now has 1 tasks, Machine 1 has 4 tasks, 72/16384 memory
[LOG] HandleTaskCompletion(): Task 112 completed at time 5076523
[LOG] Scheduler::TaskComplete(): Task 112 completed at 5076523 (target=27449823, delay=-22373300, SLA violated=NO)
[LOG] HandleNewTask(): Received new task 146 at time 5076814
[LOG] Scheduler::NewTask(): Task 146 requires VM=0 CPU=3 SLA=0 GPU=no Memory=8 TargetCompletion=30286054 Arrival=5076814
[DEBUG] Selected VM 0 with 0 active tasks on machine 0
[LOG] Scheduler::NewTask(): Task 146 placed on VM 93 (priority=0) VM now has 1 tasks, Machine 5 has 4 tasks, 72/16384 memory
[LOG] HandleNewTask(): Received new task 147 at time 5077380
[LOG] Scheduler::NewTask(): Task 147 requires VM=0 CPU=3 SLA=0 GPU=no Memory=8 TargetCompletion=27203626 Arrival=5077380
[DEBUG] Selected VM 0 with 0 active tasks on machine 0
[LOG] Scheduler::NewTask(): Task 147 placed on VM 94 (priority=0) VM now has 1 tasks, Machine 0 has 4 tasks, 80/16384 memory
[LOG] HandleNewTask(): Received new task 148 at time 5078540
[LOG] Scheduler::NewTask(): Task 148 requires VM=0 CPU=3 SLA=0 GPU=no Memory=8 TargetCompletion=28139323 Arrival=5078540
[DEBUG] Selected VM 0 with 0 active tasks on machine 0
[LOG] Scheduler::NewTask(): Task 148 placed on VM 95 (priority=0) VM now has 1 tasks, Machine 2 has 5 tasks, 80/16384 memory
[LOG] HandleNewTask(): Received new task 149 at time 5082833
[LOG] Scheduler::NewTask(): Task 149 requires VM=0 CPU=3 SLA=0 GPU=no Memory=8 TargetCompletion=29145910 Arrival=5082833
[DEBUG] Selected VM 0 with 0 active tasks on machine 0
[LOG] Scheduler::NewTask(): Task 149 placed on VM 96 (priority=0) VM now has 1 tasks, Machine 3 has 5 tasks, 80/16384 memory
[LOG] HandleNewTask(): Received new task 150 at time 5083430
[LOG] Scheduler::NewTask(): Task 150 requires VM=0 CPU=3 SLA=0 GPU=no Memory=8 TargetCompletion=27208743 Arrival=5083430
[DEBUG] Selected VM 0 with 0 active tasks on machine 0
[LOG] Scheduler::NewTask(): Task 150 placed on VM 97 (priority=0) VM now has 1 tasks, Machine 4 has 5 tasks, 80/16384 memory
[LOG] HandleNewTask(): Received new task 151 at time 5083661
[LOG] Scheduler::NewTask(): Task 151 requires VM=0 CPU=3 SLA=0 GPU=no Memory=8 TargetCompletion=27718540 Arrival=5083661
[DEBUG] Selected VM 0 with 0 active tasks on machine 0
[LOG] Scheduler::NewTask(): Task 151 placed on VM 98 (priority=0) VM now has 1 tasks, Machine 6 has 5 tasks, 80/16384 memory
[LOG] HandleNewTask(): Received new task 152 at time 5083663
[LOG] Scheduler::NewTask(): Task 152 requires VM=0 CPU=3 SLA=0 GPU=no Memory=8 TargetCompletion=27821919 Arrival=5083663
[DEBUG] Selected VM 0 with 0 active tasks on machine 0
[LOG] Scheduler::NewTask(): Task 152 placed on VM 99 (priority=0) VM now has 1 tasks, Machine 7 has 5 tasks, 80/16384 memory
[LOG] HandleTaskCompletion(): Task 132 completed at time 5086118
[LOG] Scheduler::TaskComplete(): Task 132 completed at 5086118 (target=27436487, delay=-22350369, SLA violated=NO)
[LOG] HandleNewTask(): Received new task 153 at time 5086453
[LOG] Scheduler::NewTask(): Task 153 requires VM=0 CPU=3 SLA=0 GPU=no Memory=8 TargetCompletion=30492793 Arrival=5086453
[DEBUG] Selected VM 0 with 0 active tasks on machine 0
[LOG] Scheduler::NewTask(): Task 153 placed on VM 100 (priority=0) VM now has 1 tasks, Machine 8 has 5 tasks, 80/16384 memory
[LOG] HandleNewTask(): Received new task 154 at time 5086700
[LOG] Scheduler::NewTask(): Task 154 requires VM=0 CPU=3 SLA=0 GPU=no Memory=8 TargetCompletion=28505379 Arrival=5086700
[DEBUG] Selected VM 0 with 0 active tasks on machine 0
[LOG] Scheduler::NewTask(): Task 154 placed on VM 101 (priority=0) VM now has 1 tasks, Machine 9 has 5 tasks, 80/16384 memory
[LOG] HandleNewTask(): Received new task 155 at time 5087245
[LOG] Scheduler::NewTask(): Task 155 requires VM=0 CPU=3 SLA=0 GPU=no Memory=8 TargetCompletion=28148828 Arrival=5087245
[DEBUG] Selected VM 0 with 0 active tasks on machine 0
[LOG] Scheduler::NewTask(): Task 155 placed on VM 102 (priority=0) VM now has 1 tasks, Machine 10 has 5 tasks, 80/16384 memory
[LOG] HandleNewTask(): Received new task 156 at time 5087946
[LOG] Scheduler::NewTask(): Task 156 requires VM=0 CPU=3 SLA=0 GPU=no Memory=8 TargetCompletion=29252916 Arrival=5087946
[DEBUG] Selected VM 0 with 0 active tasks on machine 0
[LOG] Scheduler::NewTask(): Task 156 placed on VM 103 (priority=0) VM now has 1 tasks, Machine 11 has 5 tasks, 80/16384 memory
[LOG] HandleNewTask(): Received new task 157 at time 5088571
[LOG] Scheduler::NewTask(): Task 157 requires VM=0 CPU=3 SLA=0 GPU=no Memory=8 TargetCompletion=31005774 Arrival=5088571
[DEBUG] Selected VM 0 with 0 active tasks on machine 0
[LOG] Scheduler::NewTask(): Task 157 placed on VM 104 (priority=0) VM now has 1 tasks, Machine 12 has 5 tasks, 80/16384 memory
[LOG] HandleNewTask(): Received new task 158 at time 5090113
[LOG] Scheduler::NewTask(): Task 158 requires VM=0 CPU=3 SLA=0 GPU=no Memory=8 TargetCompletion=28590509 Arrival=5090113
[DEBUG] Selected VM 0 with 0 active tasks on machine 0
[LOG] Scheduler::NewTask(): Task 158 placed on VM 105 (priority=0) VM now has 1 tasks, Machine 13 has 5 tasks, 80/16384 memory
[LOG] HandleNewTask(): Received new task 159 at time 5090440
[LOG] Scheduler::NewTask(): Task 159 requires VM=0 CPU=3 SLA=0 GPU=no Memory=8 TargetCompletion=27879353 Arrival=5090440
[DEBUG] Selected VM 0 with 0 active tasks on machine 0
[LOG] Scheduler::NewTask(): Task 159 placed on VM 106 (priority=0) VM now has 1 tasks, Machine 14 has 5 tasks, 80/16384 memory
[LOG] HandleNewTask(): Received new task 160 at time 5091206
[LOG] Scheduler::NewTask(): Task 160 requires VM=0 CPU=3 SLA=0 GPU=no Memory=8 TargetCompletion=31135741 Arrival=5091206
[DEBUG] Selected VM 0 with 0 active tasks on machine 0
[LOG] Scheduler::NewTask(): Task 160 placed on VM 107 (priority=0) VM now has 1 tasks, Machine 15 has 5 tasks, 80/16384 memory
[LOG] HandleNewTask(): Received new task 161 at time 5093005
[LOG] Scheduler::NewTask(): Task 161 requires VM=0 CPU=3 SLA=0 GPU=no Memory=8 TargetCompletion=29955062 Arrival=5093005
[DEBUG] Selected VM 0 with 0 active tasks on machine 0
[LOG] Scheduler::NewTask(): Task 161 placed on VM 108 (priority=0) VM now has 1 tasks, Machine 1 has 5 tasks, 88/16384 memory
[LOG] HandleNewTask(): Received new task 162 at time 5093098
[LOG] Scheduler::NewTask(): Task 162 requires VM=0 CPU=3 SLA=0 GPU=no Memory=8 TargetCompletion=29082337 Arrival=5093098
[DEBUG] Selected VM 0 with 0 active tasks on machine 0
[LOG] Scheduler::NewTask(): Task 162 placed on VM 109 (priority=0) VM now has 1 tasks, Machine 3 has 5 tasks, 88/16384 memory
[LOG] HandleNewTask(): Received new task 163 at time 5093152
[LOG] Scheduler::NewTask(): Task 163 requires VM=0 CPU=3 SLA=0 GPU=no Memory=8 TargetCompletion=28340311 Arrival=5093152
[DEBUG] Selected VM 0 with 0 active tasks on machine 0
[LOG] Scheduler::NewTask(): Task 163 placed on VM 110 (priority=0) VM now has 1 tasks, Machine 5 has 5 tasks, 88/16384 memory
[LOG] HandleNewTask(): Received new task 164 at time 5093165
[LOG] Scheduler::NewTask(): Task 164 requires VM=0 CPU=3 SLA=0 GPU=no Memory=8 TargetCompletion=27901625 Arrival=5093165
[DEBUG] Selected VM 0 with 0 active tasks on machine 0
[LOG] Scheduler::NewTask(): Task 164 placed on VM 111 (priority=0) VM now has 1 tasks, Machine 0 has 5 tasks, 96/16384 memory
[LOG] HandleNewTask(): Received new task 165 at time 5094710
[LOG] Scheduler::NewTask(): Task 165 requires VM=0 CPU=3 SLA=0 GPU=no Memory=8 TargetCompletion=28512260 Arrival=5094710
[DEBUG] Selected VM 0 with 0 active tasks on machine 0
[LOG] Scheduler::NewTask(): Task 165 placed on VM 112 (priority=0) VM now has 1 tasks, Machine 2 has 6 tasks, 96/16384 memory
[LOG] HandleNewTask(): Received new task 166 at time 5095011
[LOG] Scheduler::NewTask(): Task 166 requires VM=0 CPU=3 SLA=0 GPU=no Memory=8 TargetCompletion=30365142 Arrival=5095011
[DEBUG] Selected VM 0 with 0 active tasks on machine 0
[LOG] Scheduler::NewTask(): Task 166 placed on VM 113 (priority=0) VM now has 1 tasks, Machine 4 has 6 tasks, 96/16384 memory
[LOG] HandleNewTask(): Received new task 167 at time 5096484
[LOG] Scheduler::NewTask(): Task 167 requires VM=0 CPU=3 SLA=0 GPU=no Memory=8 TargetCompletion=30673873 Arrival=5096484
[DEBUG] Selected VM 0 with 0 active tasks on machine 0
[LOG] Scheduler::NewTask(): Task 167 placed on VM 114 (priority=0) VM now has 1 tasks, Machine 6 has 6 tasks, 96/16384 memory
[LOG] HandleNewTask(): Received new task 168 at time 5098239
[LOG] Scheduler::NewTask(): Task 168 requires VM=0 CPU=3 SLA=0 GPU=no Memory=8 TargetCompletion=30928843 Arrival=5098239
[DEBUG] Selected VM 0 with 0 active tasks on machine 0
[LOG] Scheduler::NewTask(): Task 168 placed on VM 115 (priority=0) VM now has 1 tasks, Machine 7 has 6 tasks, 96/16384 memory
[LOG] HandleNewTask(): Received new task 169 at time 5099686
[LOG] Scheduler::NewTask(): Task 169 requires VM=0 CPU=3 SLA=0 GPU=no Memory=8 TargetCompletion=29418499 Arrival=5099686
[DEBUG] Selected VM 0 with 0 active tasks on machine 0
[LOG] Scheduler::NewTask(): Task 169 placed on VM 116 (priority=0) VM now has 1 tasks, Machine 8 has 6 tasks, 96/16384 memory
[LOG] HandleNewTask(): Received new task 170 at time 5100329
[LOG] Scheduler::NewTask(): Task 170 requires VM=0 CPU=3 SLA=0 GPU=no Memory=8 TargetCompletion=27188059 Arrival=5100329
[DEBUG] Selected VM 0 with 0 active tasks on machine 0
[LOG] Scheduler::NewTask(): Task 170 placed on VM 117 (priority=0) VM now has 1 tasks, Machine 9 has 6 tasks, 96/16384 memory
[LOG] HandleNewTask(): Received new task 171 at time 5100488
[LOG] Scheduler::NewTask(): Task 171 requires VM=0 CPU=3 SLA=0 GPU=no Memory=8 TargetCompletion=29281954 Arrival=5100488
[DEBUG] Selected VM 0 with 0 active tasks on machine 0
[LOG] Scheduler::NewTask(): Task 171 placed on VM 118 (priority=0) VM now has 1 tasks, Machine 10 has 6 tasks, 96/16384 memory
[LOG] HandleNewTask(): Received new task 173 at time 5100984
[LOG] Scheduler::NewTask(): Task 173 requires VM=0 CPU=3 SLA=0 GPU=no Memory=8 TargetCompletion=30031610 Arrival=5100984
[DEBUG] Selected VM 0 with 0 active tasks on machine 0
[LOG] Scheduler::NewTask(): Task 173 placed on VM 119 (priority=0) VM now has 1 tasks, Machine 11 has 6 tasks, 96/16384 memory
[LOG] HandleNewTask(): Received new task 172 at time 5100984
[LOG] Scheduler::NewTask(): Task 172 requires VM=0 CPU=3 SLA=0 GPU=no Memory=8 TargetCompletion=30219180 Arrival=5100984
[DEBUG] Selected VM 0 with 0 active tasks on machine 0
[LOG] Scheduler::NewTask(): Task 172 placed on VM 120 (priority=0) VM now has 1 tasks, Machine 12 has 6 tasks, 96/16384 memory
[LOG] HandleNewTask(): Received new task 174 at time 5101059
[LOG] Scheduler::NewTask(): Task 174 requires VM=0 CPU=3 SLA=0 GPU=no Memory=8 TargetCompletion=30001117 Arrival=5101059
[DEBUG] Selected VM 0 with 0 active tasks on machine 0
[LOG] Scheduler::NewTask(): Task 174 placed on VM 121 (priority=0) VM now has 1 tasks, Machine 13 has 6 tasks, 96/16384 memory
[LOG] HandleNewTask(): Received new task 175 at time 5101656
[LOG] Scheduler::NewTask(): Task 175 requires VM=0 CPU=3 SLA=0 GPU=no Memory=8 TargetCompletion=29239358 Arrival=5101656
[DEBUG] Selected VM 0 with 0 active tasks on machine 0
[LOG] Scheduler::NewTask(): Task 175 placed on VM 122 (priority=0) VM now has 1 tasks, Machine 14 has 6 tasks, 96/16384 memory
[LOG] HandleNewTask(): Received new task 176 at time 5102107
[LOG] Scheduler::NewTask(): Task 176 requires VM=0 CPU=3 SLA=0 GPU=no Memory=8 TargetCompletion=29464555 Arrival=5102107
[DEBUG] Selected VM 0 with 0 active tasks on machine 0
[LOG] Scheduler::NewTask(): Task 176 placed on VM 123 (priority=0) VM now has 1 tasks, Machine 15 has 6 tasks, 96/16384 memory
[LOG] HandleNewTask(): Received new task 177 at time 5104285
[LOG] Scheduler::NewTask(): Task 177 requires VM=0 CPU=3 SLA=0 GPU=no Memory=8 TargetCompletion=28351649 Arrival=5104285
[DEBUG] Selected VM 0 with 0 active tasks on machine 0
[LOG] Scheduler::NewTask(): Task 177 placed on VM 124 (priority=0) VM now has 1 tasks, Machine 1 has 6 tasks, 104/16384 memory
[LOG] HandleNewTask(): Received new task 178 at time 5104870
[LOG] Scheduler::NewTask(): Task 178 requires VM=0 CPU=3 SLA=0 GPU=no Memory=8 TargetCompletion=27211694 Arrival=5104870
[DEBUG] Selected VM 0 with 0 active tasks on machine 0
[LOG] Scheduler::NewTask(): Task 178 placed on VM 125 (priority=0) VM now has 1 tasks, Machine 3 has 6 tasks, 104/16384 memory
[LOG] HandleNewTask(): Received new task 179 at time 5106703
[LOG] Scheduler::NewTask(): Task 179 requires VM=0 CPU=3 SLA=0 GPU=no Memory=8 TargetCompletion=28395816 Arrival=5106703
[DEBUG] Selected VM 0 with 0 active tasks on machine 0
[LOG] Scheduler::NewTask(): Task 179 placed on VM 126 (priority=0) VM now has 1 tasks, Machine 5 has 6 tasks, 104/16384 memory
[LOG] HandleNewTask(): Received new task 180 at time 5108092
[LOG] Scheduler::NewTask(): Task 180 requires VM=0 CPU=3 SLA=0 GPU=no Memory=8 TargetCompletion=28851465 Arrival=5108092
[DEBUG] Selected VM 0 with 0 active tasks on machine 0
[LOG] Scheduler::NewTask(): Task 180 placed on VM 127 (priority=0) VM now has 1 tasks, Machine 0 has 6 tasks, 112/16384 memory
[LOG] HandleNewTask(): Received new task 181 at time 5108215
[LOG] Scheduler::NewTask(): Task 181 requires VM=0 CPU=3 SLA=0 GPU=no Memory=8 TargetCompletion=30050089 Arrival=5108215
[DEBUG] Selected VM 0 with 0 active tasks on machine 0
[LOG] Scheduler::NewTask(): Task 181 placed on VM 128 (priority=0) VM now has 1 tasks, Machine 2 has 7 tasks, 112/16384 memory
[LOG] HandleNewTask(): Received new task 182 at time 5109970
[LOG] Scheduler::NewTask(): Task 182 requires VM=0 CPU=3 SLA=0 GPU=no Memory=8 TargetCompletion=30687158 Arrival=5109970
[DEBUG] Selected VM 0 with 0 active tasks on machine 0
[LOG] Scheduler::NewTask(): Task 182 placed on VM 129 (priority=0) VM now has 1 tasks, Machine 4 has 7 tasks, 112/16384 memory
[LOG] HandleNewTask(): Received new task 183 at time 5112263
[LOG] Scheduler::NewTask(): Task 183 requires VM=0 CPU=3 SLA=0 GPU=no Memory=8 TargetCompletion=28924145 Arrival=5112263
[DEBUG] Selected VM 0 with 0 active tasks on machine 0
[LOG] Scheduler::NewTask(): Task 183 placed on VM 130 (priority=0) VM now has 1 tasks, Machine 6 has 7 tasks, 112/16384 memory
[LOG] HandleNewTask(): Received new task 184 at time 5113615
[LOG] Scheduler::NewTask(): Task 184 requires VM=0 CPU=3 SLA=0 GPU=no Memory=8 TargetCompletion=28226438 Arrival=5113615
[DEBUG] Selected VM 0 with 0 active tasks on machine 0
[LOG] Scheduler::NewTask(): Task 184 placed on VM 131 (priority=0) VM now has 1 tasks, Machine 7 has 7 tasks, 112/16384 memory
[LOG] HandleNewTask(): Received new task 185 at time 5113916
[LOG] Scheduler::NewTask(): Task 185 requires VM=0 CPU=3 SLA=0 GPU=no Memory=8 TargetCompletion=31025331 Arrival=5113916
[DEBUG] Selected VM 0 with 0 active tasks on machine 0
[LOG] Scheduler::NewTask(): Task 185 placed on VM 132 (priority=0) VM now has 1 tasks, Machine 8 has 7 tasks, 112/16384 memory
[LOG] HandleNewTask(): Received new task 186 at time 5116192
[LOG] Scheduler::NewTask(): Task 186 requires VM=0 CPU=3 SLA=0 GPU=no Memory=8 TargetCompletion=30150548 Arrival=5116192
[DEBUG] Selected VM 0 with 0 active tasks on machine 0
[LOG] Scheduler::NewTask(): Task 186 placed on VM 133 (priority=0) VM now has 1 tasks, Machine 9 has 7 tasks, 112/16384 memory
[LOG] HandleNewTask(): Received new task 187 at time 5116856
[LOG] Scheduler::NewTask(): Task 187 requires VM=0 CPU=3 SLA=0 GPU=no Memory=8 TargetCompletion=30022032 Arrival=5116856
[DEBUG] Selected VM 0 with 0 active tasks on machine 0
[LOG] Scheduler::NewTask(): Task 187 placed on VM 134 (priority=0) VM now has 1 tasks, Machine 10 has 7 tasks, 112/16384 memory
[LOG] HandleNewTask(): Received new task 188 at time 5119406
[LOG] Scheduler::NewTask(): Task 188 requires VM=0 CPU=3 SLA=0 GPU=no Memory=8 TargetCompletion=28643375 Arrival=5119406
[DEBUG] Selected VM 0 with 0 active tasks on machine 0
[LOG] Scheduler::NewTask(): Task 188 placed on VM 135 (priority=0) VM now has 1 tasks, Machine 11 has 7 tasks, 112/16384 memory
[LOG] HandleNewTask(): Received new task 189 at time 5119886
[LOG] Scheduler::NewTask(): Task 189 requires VM=0 CPU=3 SLA=0 GPU=no Memory=8 TargetCompletion=28191333 Arrival=5119886
[DEBUG] Selected VM 0 with 0 active tasks on machine 0
[LOG] Scheduler::NewTask(): Task 189 placed on VM 136 (priority=0) VM now has 1 tasks, Machine 12 has 7 tasks, 112/16384 memory
[LOG] HandleNewTask(): Received new task 190 at time 5120269
[LOG] Scheduler::NewTask(): Task 190 requires VM=0 CPU=3 SLA=0 GPU=no Memory=8 TargetCompletion=29084464 Arrival=5120269
[DEBUG] Selected VM 0 with 0 active tasks on machine 0
[LOG] Scheduler::NewTask(): Task 190 placed on VM 137 (priority=0) VM now has 1 tasks, Machine 13 has 7 tasks, 112/16384 memory
[LOG] HandleNewTask(): Received new task 191 at time 5121013
[LOG] Scheduler::NewTask(): Task 191 requires VM=0 CPU=3 SLA=0 GPU=no Memory=8 TargetCompletion=27848762 Arrival=5121013
[DEBUG] Selected VM 0 with 0 active tasks on machine 0
[LOG] Scheduler::NewTask(): Task 191 placed on VM 138 (priority=0) VM now has 1 tasks, Machine 14 has 7 tasks, 112/16384 memory
[LOG] HandleNewTask(): Received new task 192 at time 5121638
[LOG] Scheduler::NewTask(): Task 192 requires VM=0 CPU=3 SLA=0 GPU=no Memory=8 TargetCompletion=27232526 Arrival=5121638
[DEBUG] Selected VM 0 with 0 active tasks on machine 0
[LOG] Scheduler::NewTask(): Task 192 placed on VM 139 (priority=0) VM now has 1 tasks, Machine 15 has 7 tasks, 112/16384 memory
[LOG] HandleNewTask(): Received new task 193 at time 5122766
[LOG] Scheduler::NewTask(): Task 193 requires VM=0 CPU=3 SLA=0 GPU=no Memory=8 TargetCompletion=28418386 Arrival=5122766
[DEBUG] Selected VM 0 with 0 active tasks on machine 0
[LOG] Scheduler::NewTask(): Task 193 placed on VM 140 (priority=0) VM now has 1 tasks, Machine 1 has 7 tasks, 120/16384 memory
[LOG] HandleNewTask(): Received new task 194 at time 5122804
[LOG] Scheduler::NewTask(): Task 194 requires VM=0 CPU=3 SLA=0 GPU=no Memory=8 TargetCompletion=30921738 Arrival=5122804
[DEBUG] Selected VM 0 with 0 active tasks on machine 0
[LOG] Scheduler::NewTask(): Task 194 placed on VM 141 (priority=0) VM now has 1 tasks, Machine 3 has 7 tasks, 120/16384 memory
[LOG] HandleNewTask(): Received new task 195 at time 5124696
[LOG] Scheduler::NewTask(): Task 195 requires VM=0 CPU=3 SLA=0 GPU=no Memory=8 TargetCompletion=30375351 Arrival=5124696
[DEBUG] Selected VM 0 with 0 active tasks on machine 0
[LOG] Scheduler::NewTask(): Task 195 placed on VM 142 (priority=0) VM now has 1 tasks, Machine 5 has 7 tasks, 120/16384 memory
[LOG] HandleNewTask(): Received new task 196 at time 5125133
[LOG] Scheduler::NewTask(): Task 196 requires VM=0 CPU=3 SLA=0 GPU=no Memory=8 TargetCompletion=30987213 Arrival=5125133
[DEBUG] Selected VM 0 with 0 active tasks on machine 0
[LOG] Scheduler::NewTask(): Task 196 placed on VM 143 (priority=0) VM now has 1 tasks, Machine 0 has 7 tasks, 128/16384 memory
[LOG] HandleNewTask(): Received new task 197 at time 5125283
[LOG] Scheduler::NewTask(): Task 197 requires VM=0 CPU=3 SLA=0 GPU=no Memory=8 TargetCompletion=30837697 Arrival=5125283
[DEBUG] Selected VM 0 with 0 active tasks on machine 0
[LOG] Scheduler::NewTask(): Task 197 placed on VM 144 (priority=0) VM now has 1 tasks, Machine 2 has 8 tasks, 128/16384 memory
[LOG] HandleNewTask(): Received new task 198 at time 5125315
[LOG] Scheduler::NewTask(): Task 198 requires VM=0 CPU=3 SLA=0 GPU=no Memory=8 TargetCompletion=27829051 Arrival=5125315
[DEBUG] Selected VM 0 with 0 active tasks on machine 0
[LOG] Scheduler::NewTask(): Task 198 placed on VM 145 (priority=0) VM now has 1 tasks, Machine 4 has 8 tasks, 128/16384 memory
[LOG] HandleNewTask(): Received new task 199 at time 5126332
[LOG] Scheduler::NewTask(): Task 199 requires VM=0 CPU=3 SLA=0 GPU=no Memory=8 TargetCompletion=27475115 Arrival=5126332
[DEBUG] Selected VM 0 with 0 active tasks on machine 0
[LOG] Scheduler::NewTask(): Task 199 placed on VM 146 (priority=0) VM now has 1 tasks, Machine 6 has 8 tasks, 128/16384 memory
[LOG] HandleNewTask(): Received new task 200 at time 5127325
[LOG] Scheduler::NewTask(): Task 200 requires VM=0 CPU=3 SLA=0 GPU=no Memory=8 TargetCompletion=28065348 Arrival=5127325
[DEBUG] Selected VM 0 with 0 active tasks on machine 0
[LOG] Scheduler::NewTask(): Task 200 placed on VM 147 (priority=0) VM now has 1 tasks, Machine 7 has 8 tasks, 128/16384 memory
[LOG] HandleNewTask(): Received new task 201 at time 5127532
[LOG] Scheduler::NewTask(): Task 201 requires VM=0 CPU=3 SLA=0 GPU=no Memory=8 TargetCompletion=30467858 Arrival=5127532
[DEBUG] Selected VM 0 with 0 active tasks on machine 0
[LOG] Scheduler::NewTask(): Task 201 placed on VM 148 (priority=0) VM now has 1 tasks, Machine 8 has 8 tasks, 128/16384 memory
[LOG] HandleNewTask(): Received new task 202 at time 5127878
[LOG] Scheduler::NewTask(): Task 202 requires VM=0 CPU=3 SLA=0 GPU=no Memory=8 TargetCompletion=28970426 Arrival=5127878
[DEBUG] Selected VM 0 with 0 active tasks on machine 0
[LOG] Scheduler::NewTask(): Task 202 placed on VM 149 (priority=0) VM now has 1 tasks, Machine 9 has 8 tasks, 128/16384 memory
[LOG] HandleNewTask(): Received new task 203 at time 5128895
[LOG] Scheduler::NewTask(): Task 203 requires VM=0 CPU=3 SLA=0 GPU=no Memory=8 TargetCompletion=28061275 Arrival=5128895
[DEBUG] Selected VM 0 with 0 active tasks on machine 0
[LOG] Scheduler::NewTask(): Task 203 placed on VM 150 (priority=0) VM now has 1 tasks, Machine 10 has 8 tasks, 128/16384 memory
[LOG] HandleNewTask(): Received new task 204 at time 5129415
[LOG] Scheduler::NewTask(): Task 204 requires VM=0 CPU=3 SLA=0 GPU=no Memory=8 TargetCompletion=30473778 Arrival=5129415
[DEBUG] Selected VM 0 with 0 active tasks on machine 0
[LOG] Scheduler::NewTask(): Task 204 placed on VM 151 (priority=0) VM now has 1 tasks, Machine 11 has 8 tasks, 128/16384 memory
[LOG] HandleNewTask(): Received new task 205 at time 5130454
[LOG] Scheduler::NewTask(): Task 205 requires VM=0 CPU=3 SLA=0 GPU=no Memory=8 TargetCompletion=29099484 Arrival=5130454
[DEBUG] Selected VM 0 with 0 active tasks on machine 0
[LOG] Scheduler::NewTask(): Task 205 placed on VM 152 (priority=0) VM now has 1 tasks, Machine 12 has 8 tasks, 128/16384 memory
[LOG] HandleNewTask(): Received new task 206 at time 5130784
[LOG] Scheduler::NewTask(): Task 206 requires VM=0 CPU=3 SLA=0 GPU=no Memory=8 TargetCompletion=29269784 Arrival=5130784
[DEBUG] Selected VM 0 with 0 active tasks on machine 0
[LOG] Scheduler::NewTask(): Task 206 placed on VM 153 (priority=0) VM now has 1 tasks, Machine 13 has 8 tasks, 128/16384 memory
[LOG] HandleNewTask(): Received new task 207 at time 5131158
[LOG] Scheduler::NewTask(): Task 207 requires VM=0 CPU=3 SLA=0 GPU=no Memory=8 TargetCompletion=27604611 Arrival=5131158
[DEBUG] Selected VM 0 with 0 active tasks on machine 0
[LOG] Scheduler::NewTask(): Task 207 placed on VM 154 (priority=0) VM now has 1 tasks, Machine 14 has 8 tasks, 128/16384 memory
[LOG] HandleNewTask(): Received new task 208 at time 5131241
[LOG] Scheduler::NewTask(): Task 208 requires VM=0 CPU=3 SLA=0 GPU=no Memory=8 TargetCompletion=28371966 Arrival=5131241
[DEBUG] Selected VM 0 with 0 active tasks on machine 0
[LOG] Scheduler::NewTask(): Task 208 placed on VM 155 (priority=0) VM now has 1 tasks, Machine 15 has 8 tasks, 128/16384 memory
[LOG] HandleNewTask(): Received new task 209 at time 5132861
[LOG] Scheduler::NewTask(): Task 209 requires VM=0 CPU=3 SLA=0 GPU=no Memory=8 TargetCompletion=30007940 Arrival=5132861
[DEBUG] Selected VM 0 with 0 active tasks on machine 0
[LOG] Scheduler::NewTask(): Task 209 placed on VM 156 (priority=0) VM now has 1 tasks, Machine 1 has 8 tasks, 136/16384 memory
[LOG] HandleNewTask(): Received new task 210 at time 5133635
[LOG] Scheduler::NewTask(): Task 210 requires VM=0 CPU=3 SLA=0 GPU=no Memory=8 TargetCompletion=30603920 Arrival=5133635
[DEBUG] Selected VM 0 with 0 active tasks on machine 0
[LOG] Scheduler::NewTask(): Task 210 placed on VM 157 (priority=0) VM now has 1 tasks, Machine 3 has 8 tasks, 136/16384 memory
[LOG] HandleNewTask(): Received new task 211 at time 5136250
[LOG] Scheduler::NewTask(): Task 211 requires VM=0 CPU=3 SLA=0 GPU=no Memory=8 TargetCompletion=27341618 Arrival=5136250
[DEBUG] Selected VM 0 with 0 active tasks on machine 0
[LOG] Scheduler::NewTask(): Task 211 placed on VM 158 (priority=0) VM now has 1 tasks, Machine 5 has 8 tasks, 136/16384 memory
[LOG] HandleNewTask(): Received new task 212 at time 5136750
[LOG] Scheduler::NewTask(): Task 212 requires VM=0 CPU=3 SLA=0 GPU=no Memory=8 TargetCompletion=29407780 Arrival=5136750
[DEBUG] Selected VM 0 with 0 active tasks on machine 0
[LOG] Scheduler::NewTask(): Task 212 placed on VM 159 (priority=0) VM now has 1 tasks, Machine 0 has 8 tasks, 144/16384 memory
[LOG] HandleNewTask(): Received new task 213 at time 5136879
[LOG] Scheduler::NewTask(): Task 213 requires VM=0 CPU=3 SLA=0 GPU=no Memory=8 TargetCompletion=28229282 Arrival=5136879
[DEBUG] Selected VM 0 with 0 active tasks on machine 0
[LOG] Scheduler::NewTask(): Task 213 placed on VM 160 (priority=0) VM now has 1 tasks, Machine 2 has 9 tasks, 144/16384 memory
[LOG] HandleNewTask(): Received new task 214 at time 5136885
[LOG] Scheduler::NewTask(): Task 214 requires VM=0 CPU=3 SLA=0 GPU=no Memory=8 TargetCompletion=28126893 Arrival=5136885
[DEBUG] Selected VM 0 with 0 active tasks on machine 0
[LOG] Scheduler::NewTask(): Task 214 placed on VM 161 (priority=0) VM now has 1 tasks, Machine 4 has 9 tasks, 144/16384 memory
[LOG] HandleNewTask(): Received new task 215 at time 5137357
[LOG] Scheduler::NewTask(): Task 215 requires VM=0 CPU=3 SLA=0 GPU=no Memory=8 TargetCompletion=30100472 Arrival=5137357
[DEBUG] Selected VM 0 with 0 active tasks on machine 0
[LOG] Scheduler::NewTask(): Task 215 placed on VM 162 (priority=0) VM now has 1 tasks, Machine 6 has 9 tasks, 144/16384 memory
[LOG] HandleNewTask(): Received new task 216 at time 5138733
[LOG] Scheduler::NewTask(): Task 216 requires VM=0 CPU=3 SLA=0 GPU=no Memory=8 TargetCompletion=28321521 Arrival=5138733
[DEBUG] Selected VM 0 with 0 active tasks on machine 0
[LOG] Scheduler::NewTask(): Task 216 placed on VM 163 (priority=0) VM now has 1 tasks, Machine 7 has 9 tasks, 144/16384 memory
[LOG] HandleNewTask(): Received new task 217 at time 5138868
[LOG] Scheduler::NewTask(): Task 217 requires VM=0 CPU=3 SLA=0 GPU=no Memory=8 TargetCompletion=28833555 Arrival=5138868
[DEBUG] Selected VM 0 with 0 active tasks on machine 0
[LOG] Scheduler::NewTask(): Task 217 placed on VM 164 (priority=0) VM now has 1 tasks, Machine 8 has 9 tasks, 144/16384 memory
[LOG] HandleNewTask(): Received new task 218 at time 5138941
[LOG] Scheduler::NewTask(): Task 218 requires VM=0 CPU=3 SLA=0 GPU=no Memory=8 TargetCompletion=27339310 Arrival=5138941
[DEBUG] Selected VM 0 with 0 active tasks on machine 0
[LOG] Scheduler::NewTask(): Task 218 placed on VM 165 (priority=0) VM now has 1 tasks, Machine 9 has 9 tasks, 144/16384 memory
[LOG] HandleNewTask(): Received new task 219 at time 5141811
[LOG] Scheduler::NewTask(): Task 219 requires VM=0 CPU=3 SLA=0 GPU=no Memory=8 TargetCompletion=30125200 Arrival=5141811
[DEBUG] Selected VM 0 with 0 active tasks on machine 0
[LOG] Scheduler::NewTask(): Task 219 placed on VM 166 (priority=0) VM now has 1 tasks, Machine 10 has 9 tasks, 144/16384 memory
[LOG] HandleTaskCompletion(): Task 199 completed at time 5144270
[LOG] Scheduler::TaskComplete(): Task 199 completed at 5144270 (target=27475115, delay=-22330845, SLA violated=NO)
[LOG] HandleNewTask(): Received new task 220 at time 5144276
[LOG] Scheduler::NewTask(): Task 220 requires VM=0 CPU=3 SLA=0 GPU=no Memory=8 TargetCompletion=27661441 Arrival=5144276
[DEBUG] Selected VM 0 with 0 active tasks on machine 0
[LOG] Scheduler::NewTask(): Task 220 placed on VM 167 (priority=0) VM now has 1 tasks, Machine 11 has 9 tasks, 144/16384 memory
[LOG] HandleNewTask(): Received new task 221 at time 5144508
[LOG] Scheduler::NewTask(): Task 221 requires VM=0 CPU=3 SLA=0 GPU=no Memory=8 TargetCompletion=30615597 Arrival=5144508
[DEBUG] Selected VM 0 with 0 active tasks on machine 0
[LOG] Scheduler::NewTask(): Task 221 placed on VM 168 (priority=0) VM now has 1 tasks, Machine 12 has 9 tasks, 144/16384 memory
[LOG] HandleNewTask(): Received new task 222 at time 5145643
[LOG] Scheduler::NewTask(): Task 222 requires VM=0 CPU=3 SLA=0 GPU=no Memory=8 TargetCompletion=30983912 Arrival=5145643
[DEBUG] Selected VM 0 with 0 active tasks on machine 0
[LOG] Scheduler::NewTask(): Task 222 placed on VM 169 (priority=0) VM now has 1 tasks, Machine 13 has 9 tasks, 144/16384 memory
[LOG] HandleNewTask(): Received new task 223 at time 5146365
[LOG] Scheduler::NewTask(): Task 223 requires VM=0 CPU=3 SLA=0 GPU=no Memory=8 TargetCompletion=29000016 Arrival=5146365
[DEBUG] Selected VM 0 with 0 active tasks on machine 0
[LOG] Scheduler::NewTask(): Task 223 placed on VM 170 (priority=0) VM now has 1 tasks, Machine 14 has 9 tasks, 144/16384 memory
[LOG] HandleNewTask(): Received new task 224 at time 5146886
[LOG] Scheduler::NewTask(): Task 224 requires VM=0 CPU=3 SLA=0 GPU=no Memory=8 TargetCompletion=31158419 Arrival=5146886
[DEBUG] Selected VM 0 with 0 active tasks on machine 0
[LOG] Scheduler::NewTask(): Task 224 placed on VM 171 (priority=0) VM now has 1 tasks, Machine 15 has 9 tasks, 144/16384 memory
[LOG] HandleNewTask(): Received new task 225 at time 5148604
[LOG] Scheduler::NewTask(): Task 225 requires VM=0 CPU=3 SLA=0 GPU=no Memory=8 TargetCompletion=30350539 Arrival=5148604
[DEBUG] Selected VM 0 with 0 active tasks on machine 0
[LOG] Scheduler::NewTask(): Task 225 placed on VM 172 (priority=0) VM now has 1 tasks, Machine 1 has 9 tasks, 152/16384 memory
[LOG] HandleNewTask(): Received new task 226 at time 5149154
[LOG] Scheduler::NewTask(): Task 226 requires VM=0 CPU=3 SLA=0 GPU=no Memory=8 TargetCompletion=29769819 Arrival=5149154
[DEBUG] Selected VM 0 with 0 active tasks on machine 0
[LOG] Scheduler::NewTask(): Task 226 placed on VM 173 (priority=0) VM now has 1 tasks, Machine 3 has 9 tasks, 152/16384 memory
[LOG] HandleNewTask(): Received new task 227 at time 5149352
[LOG] Scheduler::NewTask(): Task 227 requires VM=0 CPU=3 SLA=0 GPU=no Memory=8 TargetCompletion=27124733 Arrival=5149352
[DEBUG] Selected VM 0 with 0 active tasks on machine 0
[LOG] Scheduler::NewTask(): Task 227 placed on VM 174 (priority=0) VM now has 1 tasks, Machine 5 has 9 tasks, 152/16384 memory
[LOG] HandleNewTask(): Received new task 228 at time 5149755
[LOG] Scheduler::NewTask(): Task 228 requires VM=0 CPU=3 SLA=0 GPU=no Memory=8 TargetCompletion=28393817 Arrival=5149755
[DEBUG] Selected VM 0 with 0 active tasks on machine 0
[LOG] Scheduler::NewTask(): Task 228 placed on VM 175 (priority=0) VM now has 1 tasks, Machine 6 has 9 tasks, 152/16384 memory
[LOG] HandleNewTask(): Received new task 229 at time 5150403
[LOG] Scheduler::NewTask(): Task 229 requires VM=0 CPU=3 SLA=0 GPU=no Memory=8 TargetCompletion=27810163 Arrival=5150403
[DEBUG] Selected VM 0 with 0 active tasks on machine 0
[LOG] Scheduler::NewTask(): Task 229 placed on VM 176 (priority=0) VM now has 1 tasks, Machine 0 has 9 tasks, 160/16384 memory
[LOG] HandleTaskCompletion(): Task 93 completed at time 5152104
[LOG] Scheduler::TaskComplete(): Task 93 completed at 5152104 (target=27722329, delay=-22570225, SLA violated=NO)
[LOG] HandleNewTask(): Received new task 230 at time 5152505
[LOG] Scheduler::NewTask(): Task 230 requires VM=0 CPU=3 SLA=0 GPU=no Memory=8 TargetCompletion=29773485 Arrival=5152505
[DEBUG] Selected VM 0 with 0 active tasks on machine 0
[LOG] Scheduler::NewTask(): Task 230 placed on VM 177 (priority=0) VM now has 1 tasks, Machine 13 has 9 tasks, 152/16384 memory
[LOG] HandleNewTask(): Received new task 231 at time 5152596
[LOG] Scheduler::NewTask(): Task 231 requires VM=0 CPU=3 SLA=0 GPU=no Memory=8 TargetCompletion=29460688 Arrival=5152596
[DEBUG] Selected VM 0 with 0 active tasks on machine 0
[LOG] Scheduler::NewTask(): Task 231 placed on VM 178 (priority=0) VM now has 1 tasks, Machine 2 has 10 tasks, 160/16384 memory
[LOG] HandleNewTask(): Received new task 232 at time 5152901
[LOG] Scheduler::NewTask(): Task 232 requires VM=0 CPU=3 SLA=0 GPU=no Memory=8 TargetCompletion=30899518 Arrival=5152901
[DEBUG] Selected VM 0 with 0 active tasks on machine 0
[LOG] Scheduler::NewTask(): Task 232 placed on VM 179 (priority=0) VM now has 1 tasks, Machine 4 has 10 tasks, 160/16384 memory
[LOG] HandleNewTask(): Received new task 233 at time 5153218
[LOG] Scheduler::NewTask(): Task 233 requires VM=0 CPU=3 SLA=0 GPU=no Memory=8 TargetCompletion=30831196 Arrival=5153218
[DEBUG] Selected VM 0 with 0 active tasks on machine 0
[LOG] Scheduler::NewTask(): Task 233 placed on VM 180 (priority=0) VM now has 1 tasks, Machine 7 has 10 tasks, 160/16384 memory
[LOG] HandleNewTask(): Received new task 234 at time 5153600
[LOG] Scheduler::NewTask(): Task 234 requires VM=0 CPU=3 SLA=0 GPU=no Memory=8 TargetCompletion=28536690 Arrival=5153600
[DEBUG] Selected VM 0 with 0 active tasks on machine 0
[LOG] Scheduler::NewTask(): Task 234 placed on VM 181 (priority=0) VM now has 1 tasks, Machine 8 has 10 tasks, 160/16384 memory
[LOG] HandleNewTask(): Received new task 235 at time 5155291
[LOG] Scheduler::NewTask(): Task 235 requires VM=0 CPU=3 SLA=0 GPU=no Memory=8 TargetCompletion=27681005 Arrival=5155291
[DEBUG] Selected VM 0 with 0 active tasks on machine 0
[LOG] Scheduler::NewTask(): Task 235 placed on VM 182 (priority=0) VM now has 1 tasks, Machine 9 has 10 tasks, 160/16384 memory
[LOG] HandleNewTask(): Received new task 236 at time 5158019
[LOG] Scheduler::NewTask(): Task 236 requires VM=0 CPU=3 SLA=0 GPU=no Memory=8 TargetCompletion=31136545 Arrival=5158019
[DEBUG] Selected VM 0 with 0 active tasks on machine 0
[LOG] Scheduler::NewTask(): Task 236 placed on VM 183 (priority=0) VM now has 1 tasks, Machine 10 has 10 tasks, 160/16384 memory
[LOG] HandleNewTask(): Received new task 237 at time 5159363
[LOG] Scheduler::NewTask(): Task 237 requires VM=0 CPU=3 SLA=0 GPU=no Memory=8 TargetCompletion=28116543 Arrival=5159363
[DEBUG] Selected VM 0 with 0 active tasks on machine 0
[LOG] Scheduler::NewTask(): Task 237 placed on VM 184 (priority=0) VM now has 1 tasks, Machine 11 has 10 tasks, 160/16384 memory
[LOG] HandleNewTask(): Received new task 238 at time 5160823
[LOG] Scheduler::NewTask(): Task 238 requires VM=0 CPU=3 SLA=0 GPU=no Memory=8 TargetCompletion=27599053 Arrival=5160823
[DEBUG] Selected VM 0 with 0 active tasks on machine 0
[LOG] Scheduler::NewTask(): Task 238 placed on VM 185 (priority=0) VM now has 1 tasks, Machine 12 has 10 tasks, 160/16384 memory
[LOG] HandleNewTask(): Received new task 239 at time 5161269
[LOG] Scheduler::NewTask(): Task 239 requires VM=0 CPU=3 SLA=0 GPU=no Memory=8 TargetCompletion=28376885 Arrival=5161269
[DEBUG] Selected VM 0 with 0 active tasks on machine 0
[LOG] Scheduler::NewTask(): Task 239 placed on VM 186 (priority=0) VM now has 1 tasks, Machine 14 has 10 tasks, 160/16384 memory
[LOG] HandleNewTask(): Received new task 240 at time 5163339
[LOG] Scheduler::NewTask(): Task 240 requires VM=0 CPU=3 SLA=0 GPU=no Memory=8 TargetCompletion=29571695 Arrival=5163339
[DEBUG] Selected VM 0 with 0 active tasks on machine 0
[LOG] Scheduler::NewTask(): Task 240 placed on VM 187 (priority=0) VM now has 1 tasks, Machine 15 has 10 tasks, 160/16384 memory
[LOG] HandleNewTask(): Received new task 241 at time 5164887
[LOG] Scheduler::NewTask(): Task 241 requires VM=0 CPU=3 SLA=0 GPU=no Memory=8 TargetCompletion=27883052 Arrival=5164887
[DEBUG] Selected VM 0 with 0 active tasks on machine 0
[LOG] Scheduler::NewTask(): Task 241 placed on VM 188 (priority=0) VM now has 1 tasks, Machine 1 has 10 tasks, 168/16384 memory
[LOG] HandleNewTask(): Received new task 242 at time 5165845
[LOG] Scheduler::NewTask(): Task 242 requires VM=0 CPU=3 SLA=0 GPU=no Memory=8 TargetCompletion=30348896 Arrival=5165845
[DEBUG] Selected VM 0 with 0 active tasks on machine 0
[LOG] Scheduler::NewTask(): Task 242 placed on VM 189 (priority=0) VM now has 1 tasks, Machine 3 has 10 tasks, 168/16384 memory
[LOG] HandleNewTask(): Received new task 243 at time 5166289
[LOG] Scheduler::NewTask(): Task 243 requires VM=0 CPU=3 SLA=0 GPU=no Memory=8 TargetCompletion=27974586 Arrival=5166289
[DEBUG] Selected VM 0 with 0 active tasks on machine 0
[LOG] Scheduler::NewTask(): Task 243 placed on VM 190 (priority=0) VM now has 1 tasks, Machine 5 has 10 tasks, 168/16384 memory
[LOG] HandleNewTask(): Received new task 244 at time 5167199
[LOG] Scheduler::NewTask(): Task 244 requires VM=0 CPU=3 SLA=0 GPU=no Memory=8 TargetCompletion=28939617 Arrival=5167199
[DEBUG] Selected VM 0 with 0 active tasks on machine 0
[LOG] Scheduler::NewTask(): Task 244 placed on VM 191 (priority=0) VM now has 1 tasks, Machine 6 has 10 tasks, 168/16384 memory
[LOG] HandleNewTask(): Received new task 245 at time 5167731
[LOG] Scheduler::NewTask(): Task 245 requires VM=0 CPU=3 SLA=0 GPU=no Memory=8 TargetCompletion=27941894 Arrival=5167731
[DEBUG] Selected VM 0 with 0 active tasks on machine 0
[LOG] Scheduler::NewTask(): Task 245 placed on VM 192 (priority=0) VM now has 1 tasks, Machine 13 has 10 tasks, 168/16384 memory
[LOG] HandleNewTask(): Received new task 246 at time 5168094
[LOG] Scheduler::NewTask(): Task 246 requires VM=0 CPU=3 SLA=0 GPU=no Memory=8 TargetCompletion=31090204 Arrival=5168094
[DEBUG] Selected VM 0 with 0 active tasks on machine 0
[LOG] Scheduler::NewTask(): Task 246 placed on VM 193 (priority=0) VM now has 1 tasks, Machine 0 has 10 tasks, 176/16384 memory
[LOG] HandleNewTask(): Received new task 247 at time 5169098
[LOG] Scheduler::NewTask(): Task 247 requires VM=0 CPU=3 SLA=0 GPU=no Memory=8 TargetCompletion=30673703 Arrival=5169098
[DEBUG] Selected VM 0 with 0 active tasks on machine 0
[LOG] Scheduler::NewTask(): Task 247 placed on VM 194 (priority=0) VM now has 1 tasks, Machine 2 has 11 tasks, 176/16384 memory
[LOG] HandleNewTask(): Received new task 248 at time 5169391
[LOG] Scheduler::NewTask(): Task 248 requires VM=0 CPU=3 SLA=0 GPU=no Memory=8 TargetCompletion=31043514 Arrival=5169391
[DEBUG] Selected VM 0 with 0 active tasks on machine 0
[LOG] Scheduler::NewTask(): Task 248 placed on VM 195 (priority=0) VM now has 1 tasks, Machine 4 has 11 tasks, 176/16384 memory
[LOG] HandleNewTask(): Received new task 249 at time 5169710
[LOG] Scheduler::NewTask(): Task 249 requires VM=0 CPU=3 SLA=0 GPU=no Memory=8 TargetCompletion=29187902 Arrival=5169710
[DEBUG] Selected VM 0 with 0 active tasks on machine 0
[LOG] Scheduler::NewTask(): Task 249 placed on VM 196 (priority=0) VM now has 1 tasks, Machine 7 has 11 tasks, 176/16384 memory
[LOG] HandleNewTask(): Received new task 250 at time 5170113
[LOG] Scheduler::NewTask(): Task 250 requires VM=0 CPU=3 SLA=0 GPU=no Memory=8 TargetCompletion=28198660 Arrival=5170113
[DEBUG] Selected VM 0 with 0 active tasks on machine 0
[LOG] Scheduler::NewTask(): Task 250 placed on VM 197 (priority=0) VM now has 1 tasks, Machine 8 has 11 tasks, 176/16384 memory
[LOG] HandleNewTask(): Received new task 251 at time 5170246
[LOG] Scheduler::NewTask(): Task 251 requires VM=0 CPU=3 SLA=0 GPU=no Memory=8 TargetCompletion=30319105 Arrival=5170246
[DEBUG] Selected VM 0 with 0 active tasks on machine 0
[LOG] Scheduler::NewTask(): Task 251 placed on VM 198 (priority=0) VM now has 1 tasks, Machine 9 has 11 tasks, 176/16384 memory
[LOG] HandleNewTask(): Received new task 252 at time 5170794
[LOG] Scheduler::NewTask(): Task 252 requires VM=0 CPU=3 SLA=0 GPU=no Memory=8 TargetCompletion=29063756 Arrival=5170794
[DEBUG] Selected VM 0 with 0 active tasks on machine 0
[LOG] Scheduler::NewTask(): Task 252 placed on VM 199 (priority=0) VM now has 1 tasks, Machine 10 has 11 tasks, 176/16384 memory
[LOG] HandleNewTask(): Received new task 253 at time 5172287
[LOG] Scheduler::NewTask(): Task 253 requires VM=0 CPU=3 SLA=0 GPU=no Memory=8 TargetCompletion=30802321 Arrival=5172287
[DEBUG] Selected VM 0 with 0 active tasks on machine 0
[LOG] Scheduler::NewTask(): Task 253 placed on VM 200 (priority=0) VM now has 1 tasks, Machine 11 has 11 tasks, 176/16384 memory
[LOG] HandleNewTask(): Received new task 254 at time 5172553
[LOG] Scheduler::NewTask(): Task 254 requires VM=0 CPU=3 SLA=0 GPU=no Memory=8 TargetCompletion=28728311 Arrival=5172553
[DEBUG] Selected VM 0 with 0 active tasks on machine 0
[LOG] Scheduler::NewTask(): Task 254 placed on VM 201 (priority=0) VM now has 1 tasks, Machine 12 has 11 tasks, 176/16384 memory
[LOG] HandleNewTask(): Received new task 255 at time 5175499
[LOG] Scheduler::NewTask(): Task 255 requires VM=0 CPU=3 SLA=0 GPU=no Memory=8 TargetCompletion=28954804 Arrival=5175499
[DEBUG] Selected VM 0 with 0 active tasks on machine 0
[LOG] Scheduler::NewTask(): Task 255 placed on VM 202 (priority=0) VM now has 1 tasks, Machine 14 has 11 tasks, 176/16384 memory
[LOG] HandleNewTask(): Received new task 256 at time 5175951
[LOG] Scheduler::NewTask(): Task 256 requires VM=0 CPU=3 SLA=0 GPU=no Memory=8 TargetCompletion=29032735 Arrival=5175951
[DEBUG] Selected VM 0 with 0 active tasks on machine 0
[LOG] Scheduler::NewTask(): Task 256 placed on VM 203 (priority=0) VM now has 1 tasks, Machine 15 has 11 tasks, 176/16384 memory
[LOG] HandleNewTask(): Received new task 257 at time 5176020
[LOG] Scheduler::NewTask(): Task 257 requires VM=0 CPU=3 SLA=0 GPU=no Memory=8 TargetCompletion=29011079 Arrival=5176020
[DEBUG] Selected VM 0 with 0 active tasks on machine 0
[LOG] Scheduler::NewTask(): Task 257 placed on VM 204 (priority=0) VM now has 1 tasks, Machine 1 has 11 tasks, 184/16384 memory
[LOG] HandleNewTask(): Received new task 258 at time 5178527
[LOG] Scheduler::NewTask(): Task 258 requires VM=0 CPU=3 SLA=0 GPU=no Memory=8 TargetCompletion=30549154 Arrival=5178527
[DEBUG] Selected VM 0 with 0 active tasks on machine 0
[LOG] Scheduler::NewTask(): Task 258 placed on VM 205 (priority=0) VM now has 1 tasks, Machine 3 has 11 tasks, 184/16384 memory
[LOG] HandleNewTask(): Received new task 259 at time 5178890
[LOG] Scheduler::NewTask(): Task 259 requires VM=0 CPU=3 SLA=0 GPU=no Memory=8 TargetCompletion=27852828 Arrival=5178890
[DEBUG] Selected VM 0 with 0 active tasks on machine 0
[LOG] Scheduler::NewTask(): Task 259 placed on VM 206 (priority=0) VM now has 1 tasks, Machine 5 has 11 tasks, 184/16384 memory
[LOG] HandleNewTask(): Received new task 260 at time 5179680
[LOG] Scheduler::NewTask(): Task 260 requires VM=0 CPU=3 SLA=0 GPU=no Memory=8 TargetCompletion=29897687 Arrival=5179680
[DEBUG] Selected VM 0 with 0 active tasks on machine 0
[LOG] Scheduler::NewTask(): Task 260 placed on VM 207 (priority=0) VM now has 1 tasks, Machine 6 has 11 tasks, 184/16384 memory
[LOG] HandleNewTask(): Received new task 261 at time 5180394
[LOG] Scheduler::NewTask(): Task 261 requires VM=0 CPU=3 SLA=0 GPU=no Memory=8 TargetCompletion=28553913 Arrival=5180394
[DEBUG] Selected VM 0 with 0 active tasks on machine 0
[LOG] Scheduler::NewTask(): Task 261 placed on VM 208 (priority=0) VM now has 1 tasks, Machine 13 has 11 tasks, 184/16384 memory
[LOG] HandleTaskCompletion(): Task 88 completed at time 5183856
[LOG] Scheduler::TaskComplete(): Task 88 completed at 5183856 (target=27826838, delay=-22642982, SLA violated=NO)
[LOG] Scheduler::consolidateMachines(): Powering down idle machine 16 (active machines: 24)
[LOG] Scheduler::consolidateMachines(): Powering down idle machine 17 (active machines: 23)
[LOG] Scheduler::consolidateMachines(): Powering down idle machine 18 (active machines: 22)
[LOG] Scheduler::consolidateMachines(): Powering down idle machine 19 (active machines: 21)
[LOG] Scheduler::consolidateMachines(): Powering down idle machine 20 (active machines: 20)
[LOG] Scheduler::consolidateMachines(): Powering down idle machine 21 (active machines: 19)
[LOG] Scheduler::consolidateMachines(): Powering down idle machine 22 (active machines: 18)
[LOG] Scheduler::consolidateMachines(): Powering down idle machine 23 (active machines: 17)
[LOG] HandleNewTask(): Received new task 262 at time 5184842
[LOG] Scheduler::NewTask(): Task 262 requires VM=0 CPU=3 SLA=0 GPU=no Memory=8 TargetCompletion=30917925 Arrival=5184842
[DEBUG] Selected VM 0 with 0 active tasks on machine 0
[LOG] Scheduler::NewTask(): Task 262 placed on VM 209 (priority=0) VM now has 1 tasks, Machine 8 has 11 tasks, 184/16384 memory
[LOG] HandleNewTask(): Received new task 263 at time 5185314
[LOG] Scheduler::NewTask(): Task 263 requires VM=0 CPU=3 SLA=0 GPU=no Memory=8 TargetCompletion=28368230 Arrival=5185314
[DEBUG] Selected VM 0 with 0 active tasks on machine 0
[LOG] Scheduler::NewTask(): Task 263 placed on VM 210 (priority=0) VM now has 1 tasks, Machine 0 has 11 tasks, 192/16384 memory
[LOG] HandleNewTask(): Received new task 264 at time 5187486
[LOG] Scheduler::NewTask(): Task 264 requires VM=0 CPU=3 SLA=0 GPU=no Memory=8 TargetCompletion=31126777 Arrival=5187486
[DEBUG] Selected VM 0 with 0 active tasks on machine 0
[LOG] Scheduler::NewTask(): Task 264 placed on VM 211 (priority=0) VM now has 1 tasks, Machine 2 has 12 tasks, 192/16384 memory
[LOG] HandleNewTask(): Received new task 265 at time 5188152
[LOG] Scheduler::NewTask(): Task 265 requires VM=0 CPU=3 SLA=0 GPU=no Memory=8 TargetCompletion=29200666 Arrival=5188152
[DEBUG] Selected VM 0 with 0 active tasks on machine 0
[LOG] Scheduler::NewTask(): Task 265 placed on VM 212 (priority=0) VM now has 1 tasks, Machine 4 has 12 tasks, 192/16384 memory
[LOG] HandleNewTask(): Received new task 266 at time 5189493
[LOG] Scheduler::NewTask(): Task 266 requires VM=0 CPU=3 SLA=0 GPU=no Memory=8 TargetCompletion=29773990 Arrival=5189493
[DEBUG] Selected VM 0 with 0 active tasks on machine 0
[LOG] Scheduler::NewTask(): Task 266 placed on VM 213 (priority=0) VM now has 1 tasks, Machine 7 has 12 tasks, 192/16384 memory
[LOG] HandleNewTask(): Received new task 267 at time 5189802
[LOG] Scheduler::NewTask(): Task 267 requires VM=0 CPU=3 SLA=0 GPU=no Memory=8 TargetCompletion=29195531 Arrival=5189802
[DEBUG] Selected VM 0 with 0 active tasks on machine 0
[LOG] Scheduler::NewTask(): Task 267 placed on VM 214 (priority=0) VM now has 1 tasks, Machine 9 has 12 tasks, 192/16384 memory
[LOG] HandleNewTask(): Received new task 268 at time 5189855
[LOG] Scheduler::NewTask(): Task 268 requires VM=0 CPU=3 SLA=0 GPU=no Memory=8 TargetCompletion=28831129 Arrival=5189855
[DEBUG] Selected VM 0 with 0 active tasks on machine 0
[LOG] Scheduler::NewTask(): Task 268 placed on VM 215 (priority=0) VM now has 1 tasks, Machine 10 has 12 tasks, 192/16384 memory
[LOG] HandleNewTask(): Received new task 269 at time 5189934
[LOG] Scheduler::NewTask(): Task 269 requires VM=0 CPU=3 SLA=0 GPU=no Memory=8 TargetCompletion=27441257 Arrival=5189934
[DEBUG] Selected VM 0 with 0 active tasks on machine 0
[LOG] Scheduler::NewTask(): Task 269 placed on VM 216 (priority=0) VM now has 1 tasks, Machine 11 has 12 tasks, 192/16384 memory
[LOG] HandleNewTask(): Received new task 270 at time 5189968
